Workbook

Sheet HOME
B2: Months | D2: Months

Sheet JAN
D2: DASHBOARD | G2: Daily Sales Report (Dine in, Take Away, Delivery) | S2: Consolidated
C3: Month | D3: January | G3: S.no | H3: Date | I3: Day | J3: Dine In sales | K3: Dine In Tickets | L3: APC / APT | M3: Take Away sales | N3: Take Away Tickets | O3: APC / APT | P3: Delivery sales | Q3: Delivery Tickets | R3: APC / APT | S3: Target Sales | T3: Total Sales | U3: Total Ticket | V3: APC / APT | W3: Target vs Achieved | X3: %
G4: 1 | H4: =D7 -> 45658 | I4: =TEXT(H4,"DDD") -> Wed | J4: 15000 | K4: 24 | L4: =IF(J4=0,"",J4/K4) -> 625 | M4: 7000 | N4: 35 | O4: =IF(M4=0,"",M4/N4) -> 200 | P4: 6000 | Q4: 36 | R4: =IF(P4=0,"",P4/Q4) -> 166.66667 | S4: 20000 | T4: =IF(J4=0,"",J4+M4+P4) -> 28000 | U4: =IF(T4="","",K4+N4+Q4) -> 95 | V4: =IF(U4="","",T4/U4) -> 294.73684 | W4: =IFERROR(T4-S4,"") -> 8000 | X4: =IF(S4=0,"",T4/S4) -> 1.4
C5: Year | D5: 2025 | G5: 2 | H5: =IF(H4<$D$9,H4+1,"EOM") -> 45659 | I5: =TEXT(H5,"DDD") -> Thu | J5: 12000 | K5: 45 | L5: =IF(J5=0,"",J5/K5) -> 266.66667 | M5: 5500 | N5: 50 | O5: =IF(M5=0,"",M5/N5) -> 110 | P5: 5321 | Q5: 34 | R5: =IF(P5=0,"",P5/Q5) -> 156.5 | S5: 20000 | T5: =IF(J5=0,"",J5+M5+P5) -> 22821 | U5: =IF(T5="","",K5+N5+Q5) -> 129 | V5: =IF(U5="","",T5/U5) -> 176.90698 | W5: =IFERROR(T5-S5,"") -> 2821 | X5: =IF(S5=0,"",T5/S5) -> 1.14105
G6: 3 | H6: =IF(H5<$D$9,H5+1,"EOM") -> 45660 | I6: =TEXT(H6,"DDD") -> Fri | J6: 14000 | K6: 46 | L6: =IF(J6=0,"",J6/K6) -> 304.34783 | M6: 5600 | N6: 40 | O6: =IF(M6=0,"",M6/N6) -> 140 | P6: 1200 | Q6: 24 | R6: =IF(P6=0,"",P6/Q6) -> 50 | S6: 20000 | T6: =IF(J6=0,"",J6+M6+P6) -> 20800 | U6: =IF(T6="","",K6+N6+Q6) -> 110 | V6: =IF(U6="","",T6/U6) -> 189.09091 | W6: =IFERROR(T6-S6,"") -> 800 | X6: =IF(S6=0,"",T6/S6) -> 1.04
C7: Start Date | D7: =DATEVALUE("1"& D3 & D5) -> 45658 | G7: 4 | H7: =IF(H6<$D$9,H6+1,"EOM") -> 45661 | I7: =TEXT(H7,"DDD") -> Sat | J7: 11000 | K7: 35 | L7: =IF(J7=0,"",J7/K7) -> 314.28571 | M7: 5800 | N7: 36 | O7: =IF(M7=0,"",M7/N7) -> 161.11111 | P7: 2200 | Q7: 45 | R7: =IF(P7=0,"",P7/Q7) -> 48.888889 | S7: 20000 | T7: =IF(J7=0,"",J7+M7+P7) -> 19000 | U7: =IF(T7="","",K7+N7+Q7) -> 116 | V7: =IF(U7="","",T7/U7) -> 163.7931 | W7: =IFERROR(T7-S7,"") -> -1000 | X7: =IF(S7=0,"",T7/S7) -> 0.95
G8: 5 | H8: =IF(H7<$D$9,H7+1,"EOM") -> 45662 | I8: =TEXT(H8,"DDD") -> Sun | J8: 10000 | K8: 50 | L8: =IF(J8=0,"",J8/K8) -> 200 | M8: 7100 | N8: 34 | O8: =IF(M8=0,"",M8/N8) -> 208.82353 | P8: 2415 | Q8: 46 | R8: =IF(P8=0,"",P8/Q8) -> 52.5 | S8: 20000 | T8: =IF(J8=0,"",J8+M8+P8) -> 19515 | U8: =IF(T8="","",K8+N8+Q8) -> 130 | V8: =IF(U8="","",T8/U8) -> 150.11538 | W8: =IFERROR(T8-S8,"") -> -485 | X8: =IF(S8=0,"",T8/S8) -> 0.97575
C9: End Date | D9: =EOMONTH(D7, 0) -> 45688 | G9: 6 | H9: =IF(H8<$D$9,H8+1,"EOM") -> 45663 | I9: =TEXT(H9,"DDD") -> Mon | J9: 16000 | K9: 40 | L9: =IF(J9=0,"",J9/K9) -> 400 | M9: 6500 | N9: 24 | O9: =IF(M9=0,"",M9/N9) -> 270.83333 | P9: 2561 | Q9: 35 | R9: =IF(P9=0,"",P9/Q9) -> 73.171429 | S9: 20000 | T9: =IF(J9=0,"",J9+M9+P9) -> 25061 | U9: =IF(T9="","",K9+N9+Q9) -> 99 | V9: =IF(U9="","",T9/U9) -> 253.14141 | W9: =IFERROR(T9-S9,"") -> 5061 | X9: =IF(S9=0,"",T9/S9) -> 1.25305
G10: 7 | H10: =IF(H9<$D$9,H9+1,"EOM") -> 45664 | I10: =TEXT(H10,"DDD") -> Tue | J10: 12000 | K10: 36 | L10: =IF(J10=0,"",J10/K10) -> 333.33333 | M10: 6200 | N10: 45 | O10: =IF(M10=0,"",M10/N10) -> 137.77778 | P10: 3214 | Q10: 50 | R10: =IF(P10=0,"",P10/Q10) -> 64.28 | S10: 20000 | T10: =IF(J10=0,"",J10+M10+P10) -> 21414 | U10: =IF(T10="","",K10+N10+Q10) -> 131 | V10: =IF(U10="","",T10/U10) -> 163.46565 | W10: =IFERROR(T10-S10,"") -> 1414 | X10: =IF(S10=0,"",T10/S10) -> 1.0707
C11: Total Days | D11: =COUNT(H4:H34) -> 31 | G11: 8 | H11: =IF(H10<$D$9,H10+1,"EOM") -> 45665 | I11: =TEXT(H11,"DDD") -> Wed | J11: 11000 | K11: 34 | L11: =IF(J11=0,"",J11/K11) -> 323.52941 | M11: 4500 | N11: 46 | O11: =IF(M11=0,"",M11/N11) -> 97.826087 | P11: 2315 | Q11: 40 | R11: =IF(P11=0,"",P11/Q11) -> 57.875 | S11: 20000 | T11: =IF(J11=0,"",J11+M11+P11) -> 17815 | U11: =IF(T11="","",K11+N11+Q11) -> 120 | V11: =IF(U11="","",T11/U11) -> 148.45833 | W11: =IFERROR(T11-S11,"") -> -2185 | X11: =IF(S11=0,"",T11/S11) -> 0.89075
G12: 9 | H12: =IF(H11<$D$9,H11+1,"EOM") -> 45666 | I12: =TEXT(H12,"DDD") -> Thu | J12: 15000 | K12: 24 | L12: =IF(J12=0,"",J12/K12) -> 625 | M12: 7200 | N12: 35 | O12: =IF(M12=0,"",M12/N12) -> 205.71429 | P12: 3524 | Q12: 36 | R12: =IF(P12=0,"",P12/Q12) -> 97.888889 | S12: 20000 | T12: =IF(J12=0,"",J12+M12+P12) -> 25724 | U12: =IF(T12="","",K12+N12+Q12) -> 95 | V12: =IF(U12="","",T12/U12) -> 270.77895 | W12: =IFERROR(T12-S12,"") -> 5724 | X12: =IF(S12=0,"",T12/S12) -> 1.2862
C13: Total Saturday | D13: =COUNTIF(I4:I34,"Sat") -> 4 | G13: 10 | H13: =IF(H12<$D$9,H12+1,"EOM") -> 45667 | I13: =TEXT(H13,"DDD") -> Fri | J13: 12000 | K13: 45 | L13: =IF(J13=0,"",J13/K13) -> 266.66667 | M13: 6900 | N13: 50 | O13: =IF(M13=0,"",M13/N13) -> 138 | P13: 3621 | Q13: 34 | R13: =IF(P13=0,"",P13/Q13) -> 106.5 | S13: 20000 | T13: =IF(J13=0,"",J13+M13+P13) -> 22521 | U13: =IF(T13="","",K13+N13+Q13) -> 129 | V13: =IF(U13="","",T13/U13) -> 174.5814 | W13: =IFERROR(T13-S13,"") -> 2521 | X13: =IF(S13=0,"",T13/S13) -> 1.12605
C14: Total Sunday | D14: =COUNTIF(I4:I34,"Sun") -> 4 | G14: 11 | H14: =IF(H13<$D$9,H13+1,"EOM") -> 45668 | I14: =TEXT(H14,"DDD") -> Sat | J14: 14000 | K14: 46 | L14: =IF(J14=0,"",J14/K14) -> 304.34783 | M14: 5900 | N14: 40 | O14: =IF(M14=0,"",M14/N14) -> 147.5 | P14: 1200 | Q14: 45 | R14: =IF(P14=0,"",P14/Q14) -> 26.666667 | S14: 20000 | T14: =IF(J14=0,"",J14+M14+P14) -> 21100 | U14: =IF(T14="","",K14+N14+Q14) -> 131 | V14: =IF(U14="","",T14/U14) -> 161.0687 | W14: =IFERROR(T14-S14,"") -> 1100 | X14: =IF(S14=0,"",T14/S14) -> 1.055
G15: 12 | H15: =IF(H14<$D$9,H14+1,"EOM") -> 45669 | I15: =TEXT(H15,"DDD") -> Sun | J15: 11000 | K15: 35 | L15: =IF(J15=0,"",J15/K15) -> 314.28571 | M15: 7500 | N15: 36 | O15: =IF(M15=0,"",M15/N15) -> 208.33333 | P15: 850 | Q15: 46 | R15: =IF(P15=0,"",P15/Q15) -> 18.478261 | S15: 20000 | T15: =IF(J15=0,"",J15+M15+P15) -> 19350 | U15: =IF(T15="","",K15+N15+Q15) -> 117 | V15: =IF(U15="","",T15/U15) -> 165.38462 | W15: =IFERROR(T15-S15,"") -> -650 | X15: =IF(S15=0,"",T15/S15) -> 0.9675
C16: Highest sales for the day | D16: =MAX(T4:T34) -> 28000 | G16: 13 | H16: =IF(H15<$D$9,H15+1,"EOM") -> 45670 | I16: =TEXT(H16,"DDD") -> Mon | J16: 10000 | K16: 50 | L16: =IF(J16=0,"",J16/K16) -> 200 | M16: 5800 | N16: 34 | O16: =IF(M16=0,"",M16/N16) -> 170.58824 | P16: 1421 | Q16: 35 | R16: =IF(P16=0,"",P16/Q16) -> 40.6 | S16: 20000 | T16: =IF(J16=0,"",J16+M16+P16) -> 17221 | U16: =IF(T16="","",K16+N16+Q16) -> 119 | V16: =IF(U16="","",T16/U16) -> 144.71429 | W16: =IFERROR(T16-S16,"") -> -2779 | X16: =IF(S16=0,"",T16/S16) -> 0.86105
G17: 14 | H17: =IF(H16<$D$9,H16+1,"EOM") -> 45671 | I17: =TEXT(H17,"DDD") -> Tue | J17: 16000 | K17: 40 | L17: =IF(J17=0,"",J17/K17) -> 400 | M17: 4500 | N17: 45 | O17: =IF(M17=0,"",M17/N17) -> 100 | P17: 1562 | Q17: 50 | R17: =IF(P17=0,"",P17/Q17) -> 31.24 | S17: 20000 | T17: =IF(J17=0,"",J17+M17+P17) -> 22062 | U17: =IF(T17="","",K17+N17+Q17) -> 135 | V17: =IF(U17="","",T17/U17) -> 163.42222 | W17: =IFERROR(T17-S17,"") -> 2062 | X17: =IF(S17=0,"",T17/S17) -> 1.1031
C18: Lowest sales for the day | D18: =MIN(T4:T34) -> 16300 | G18: 15 | H18: =IF(H17<$D$9,H17+1,"EOM") -> 45672 | I18: =TEXT(H18,"DDD") -> Wed | J18: 12000 | K18: 36 | L18: =IF(J18=0,"",J18/K18) -> 333.33333 | M18: 4900 | N18: 46 | O18: =IF(M18=0,"",M18/N18) -> 106.52174 | P18: 1900 | Q18: 40 | R18: =IF(P18=0,"",P18/Q18) -> 47.5 | S18: 20000 | T18: =IF(J18=0,"",J18+M18+P18) -> 18800 | U18: =IF(T18="","",K18+N18+Q18) -> 122 | V18: =IF(U18="","",T18/U18) -> 154.09836 | W18: =IFERROR(T18-S18,"") -> -1200 | X18: =IF(S18=0,"",T18/S18) -> 0.94
G19: 16 | H19: =IF(H18<$D$9,H18+1,"EOM") -> 45673 | I19: =TEXT(H19,"DDD") -> Thu | J19: 11000 | K19: 34 | L19: =IF(J19=0,"",J19/K19) -> 323.52941 | M19: 3200 | N19: 35 | O19: =IF(M19=0,"",M19/N19) -> 91.428571 | P19: 2100 | Q19: 36 | R19: =IF(P19=0,"",P19/Q19) -> 58.333333 | S19: 20000 | T19: =IF(J19=0,"",J19+M19+P19) -> 16300 | U19: =IF(T19="","",K19+N19+Q19) -> 105 | V19: =IF(U19="","",T19/U19) -> 155.2381 | W19: =IFERROR(T19-S19,"") -> -3700 | X19: =IF(S19=0,"",T19/S19) -> 0.815
C20: Target Achieved | D20: =IF(T35>S35,"Yes","No") -> Yes | G20: 17 | H20: =IF(H19<$D$9,H19+1,"EOM") -> 45674 | I20: =TEXT(H20,"DDD") -> Fri | J20: 15000 | K20: 24 | L20: =IF(J20=0,"",J20/K20) -> 625 | M20: 4600 | N20: 50 | O20: =IF(M20=0,"",M20/N20) -> 92 | P20: 2135 | Q20: 34 | R20: =IF(P20=0,"",P20/Q20) -> 62.794118 | S20: 20000 | T20: =IF(J20=0,"",J20+M20+P20) -> 21735 | U20: =IF(T20="","",K20+N20+Q20) -> 108 | V20: =IF(U20="","",T20/U20) -> 201.25 | W20: =IFERROR(T20-S20,"") -> 1735 | X20: =IF(S20=0,"",T20/S20) -> 1.08675
G21: 18 | H21: =IF(H20<$D$9,H20+1,"EOM") -> 45675 | I21: =TEXT(H21,"DDD") -> Sat | J21: 12000 | K21: 45 | L21: =IF(J21=0,"",J21/K21) -> 266.66667 | M21: 5600 | N21: 40 | O21: =IF(M21=0,"",M21/N21) -> 140 | P21: 2362 | Q21: 24 | R21: =IF(P21=0,"",P21/Q21) -> 98.416667 | S21: 20000 | T21: =IF(J21=0,"",J21+M21+P21) -> 19962 | U21: =IF(T21="","",K21+N21+Q21) -> 109 | V21: =IF(U21="","",T21/U21) -> 183.13761 | W21: =IFERROR(T21-S21,"") -> -38 | X21: =IF(S21=0,"",T21/S21) -> 0.9981
C22: Sales till date | D22: =T35 -> 652247 | G22: 19 | H22: =IF(H21<$D$9,H21+1,"EOM") -> 45676 | I22: =TEXT(H22,"DDD") -> Sun | J22: 14000 | K22: 46 | L22: =IF(J22=0,"",J22/K22) -> 304.34783 | M22: 4500 | N22: 36 | O22: =IF(M22=0,"",M22/N22) -> 125 | P22: 3521 | Q22: 45 | R22: =IF(P22=0,"",P22/Q22) -> 78.244444 | S22: 20000 | T22: =IF(J22=0,"",J22+M22+P22) -> 22021 | U22: =IF(T22="","",K22+N22+Q22) -> 127 | V22: =IF(U22="","",T22/U22) -> 173.3937 | W22: =IFERROR(T22-S22,"") -> 2021 | X22: =IF(S22=0,"",T22/S22) -> 1.10105
G23: 20 | H23: =IF(H22<$D$9,H22+1,"EOM") -> 45677 | I23: =TEXT(H23,"DDD") -> Mon | J23: 11000 | K23: 35 | L23: =IF(J23=0,"",J23/K23) -> 314.28571 | M23: 7500 | N23: 34 | O23: =IF(M23=0,"",M23/N23) -> 220.58824 | P23: 3254 | Q23: 46 | R23: =IF(P23=0,"",P23/Q23) -> 70.73913 | S23: 20000 | T23: =IF(J23=0,"",J23+M23+P23) -> 21754 | U23: =IF(T23="","",K23+N23+Q23) -> 115 | V23: =IF(U23="","",T23/U23) -> 189.16522 | W23: =IFERROR(T23-S23,"") -> 1754 | X23: =IF(S23=0,"",T23/S23) -> 1.0877
C24: Average sales | D24: =AVERAGE(T4:T34) -> 21040.226 | G24: 21 | H24: =IF(H23<$D$9,H23+1,"EOM") -> 45678 | I24: =TEXT(H24,"DDD") -> Tue | J24: 10000 | K24: 50 | L24: =IF(J24=0,"",J24/K24) -> 200 | M24: 5900 | N24: 24 | O24: =IF(M24=0,"",M24/N24) -> 245.83333 | P24: 2651 | Q24: 35 | R24: =IF(P24=0,"",P24/Q24) -> 75.742857 | S24: 20000 | T24: =IF(J24=0,"",J24+M24+P24) -> 18551 | U24: =IF(T24="","",K24+N24+Q24) -> 109 | V24: =IF(U24="","",T24/U24) -> 170.19266 | W24: =IFERROR(T24-S24,"") -> -1449 | X24: =IF(S24=0,"",T24/S24) -> 0.92755
G25: 22 | H25: =IF(H24<$D$9,H24+1,"EOM") -> 45679 | I25: =TEXT(H25,"DDD") -> Wed | J25: 16000 | K25: 40 | L25: =IF(J25=0,"",J25/K25) -> 400 | M25: 6200 | N25: 45 | O25: =IF(M25=0,"",M25/N25) -> 137.77778 | P25: 2548 | Q25: 50 | R25: =IF(P25=0,"",P25/Q25) -> 50.96 | S25: 20000 | T25: =IF(J25=0,"",J25+M25+P25) -> 24748 | U25: =IF(T25="","",K25+N25+Q25) -> 135 | V25: =IF(U25="","",T25/U25) -> 183.31852 | W25: =IFERROR(T25-S25,"") -> 4748 | X25: =IF(S25=0,"",T25/S25) -> 1.2374
C26: Dine in sales | D26: =J35 -> 398000 | G26: 23 | H26: =IF(H25<$D$9,H25+1,"EOM") -> 45680 | I26: =TEXT(H26,"DDD") -> Thu | J26: 12000 | K26: 36 | L26: =IF(J26=0,"",J26/K26) -> 333.33333 | M26: 6321 | N26: 46 | O26: =IF(M26=0,"",M26/N26) -> 137.41304 | P26: 950 | Q26: 40 | R26: =IF(P26=0,"",P26/Q26) -> 23.75 | S26: 20000 | T26: =IF(J26=0,"",J26+M26+P26) -> 19271 | U26: =IF(T26="","",K26+N26+Q26) -> 122 | V26: =IF(U26="","",T26/U26) -> 157.95902 | W26: =IFERROR(T26-S26,"") -> -729 | X26: =IF(S26=0,"",T26/S26) -> 0.96355
C27: Take away sales | D27: =M35 -> 180483 | G27: 24 | H27: =IF(H26<$D$9,H26+1,"EOM") -> 45681 | I27: =TEXT(H27,"DDD") -> Fri | J27: 11000 | K27: 34 | L27: =IF(J27=0,"",J27/K27) -> 323.52941 | M27: 5621 | N27: 35 | O27: =IF(M27=0,"",M27/N27) -> 160.6 | P27: 1254 | Q27: 36 | R27: =IF(P27=0,"",P27/Q27) -> 34.833333 | S27: 20000 | T27: =IF(J27=0,"",J27+M27+P27) -> 17875 | U27: =IF(T27="","",K27+N27+Q27) -> 105 | V27: =IF(U27="","",T27/U27) -> 170.2381 | W27: =IFERROR(T27-S27,"") -> -2125 | X27: =IF(S27=0,"",T27/S27) -> 0.89375
C28: Delivery sales | D28: =P35 -> 73764 | G28: 25 | H28: =IF(H27<$D$9,H27+1,"EOM") -> 45682 | I28: =TEXT(H28,"DDD") -> Sat | J28: 11000 | K28: 45 | L28: =IF(J28=0,"",J28/K28) -> 244.44444 | M28: 4856 | N28: 50 | O28: =IF(M28=0,"",M28/N28) -> 97.12 | P28: 1456 | Q28: 34 | R28: =IF(P28=0,"",P28/Q28) -> 42.823529 | S28: 20000 | T28: =IF(J28=0,"",J28+M28+P28) -> 17312 | U28: =IF(T28="","",K28+N28+Q28) -> 129 | V28: =IF(U28="","",T28/U28) -> 134.20155 | W28: =IFERROR(T28-S28,"") -> -2688 | X28: =IF(S28=0,"",T28/S28) -> 0.8656
G29: 26 | H29: =IF(H28<$D$9,H28+1,"EOM") -> 45683 | I29: =TEXT(H29,"DDD") -> Sun | J29: 10000 | K29: 46 | L29: =IF(J29=0,"",J29/K29) -> 217.3913 | M29: 5421 | N29: 40 | O29: =IF(M29=0,"",M29/N29) -> 135.525 | P29: 2540 | Q29: 45 | R29: =IF(P29=0,"",P29/Q29) -> 56.444444 | S29: 20000 | T29: =IF(J29=0,"",J29+M29+P29) -> 17961 | U29: =IF(T29="","",K29+N29+Q29) -> 131 | V29: =IF(U29="","",T29/U29) -> 137.10687 | W29: =IFERROR(T29-S29,"") -> -2039 | X29: =IF(S29=0,"",T29/S29) -> 0.89805
C30: Total sales | D30: =SUM(D26:D28) -> 652247 | G30: 27 | H30: =IF(H29<$D$9,H29+1,"EOM") -> 45684 | I30: =TEXT(H30,"DDD") -> Mon | J30: 16000 | K30: 35 | L30: =IF(J30=0,"",J30/K30) -> 457.14286 | M30: 5962 | N30: 36 | O30: =IF(M30=0,"",M30/N30) -> 165.61111 | P30: 2632 | Q30: 46 | R30: =IF(P30=0,"",P30/Q30) -> 57.217391 | S30: 20000 | T30: =IF(J30=0,"",J30+M30+P30) -> 24594 | U30: =IF(T30="","",K30+N30+Q30) -> 117 | V30: =IF(U30="","",T30/U30) -> 210.20513 | W30: =IFERROR(T30-S30,"") -> 4594 | X30: =IF(S30=0,"",T30/S30) -> 1.2297
C31: last year sales | D31: 710023 | G31: 28 | H31: =IF(H30<$D$9,H30+1,"EOM") -> 45685 | I31: =TEXT(H31,"DDD") -> Tue | J31: 12000 | K31: 50 | L31: =IF(J31=0,"",J31/K31) -> 240 | M31: 6521 | N31: 34 | O31: =IF(M31=0,"",M31/N31) -> 191.79412 | P31: 1100 | Q31: 35 | R31: =IF(P31=0,"",P31/Q31) -> 31.428571 | S31: 20000 | T31: =IF(J31=0,"",J31+M31+P31) -> 19621 | U31: =IF(T31="","",K31+N31+Q31) -> 119 | V31: =IF(U31="","",T31/U31) -> 164.88235 | W31: =IFERROR(T31-S31,"") -> -379 | X31: =IF(S31=0,"",T31/S31) -> 0.98105
G32: 29 | H32: =IF(H31<$D$9,H31+1,"EOM") -> 45686 | I32: =TEXT(H32,"DDD") -> Wed | J32: 11000 | K32: 40 | L32: =IF(J32=0,"",J32/K32) -> 275 | M32: 6321 | N32: 45 | O32: =IF(M32=0,"",M32/N32) -> 140.46667 | P32: 1562 | Q32: 50 | R32: =IF(P32=0,"",P32/Q32) -> 31.24 | S32: 20000 | T32: =IF(J32=0,"",J32+M32+P32) -> 18883 | U32: =IF(T32="","",K32+N32+Q32) -> 135 | V32: =IF(U32="","",T32/U32) -> 139.87407 | W32: =IFERROR(T32-S32,"") -> -1117 | X32: =IF(S32=0,"",T32/S32) -> 0.94415
C33: Growth | D33: =D30-D31 -> -57776 | G33: 30 | H33: =IF(H32<$D$9,H32+1,"EOM") -> 45687 | I33: =TEXT(H33,"DDD") -> Thu | J33: 18000 | K33: 36 | L33: =IF(J33=0,"",J33/K33) -> 500 | M33: 6548 | N33: 46 | O33: =IF(M33=0,"",M33/N33) -> 142.34783 | P33: 1995 | Q33: 40 | R33: =IF(P33=0,"",P33/Q33) -> 49.875 | S33: 20000 | T33: =IF(J33=0,"",J33+M33+P33) -> 26543 | U33: =IF(T33="","",K33+N33+Q33) -> 122 | V33: =IF(U33="","",T33/U33) -> 217.56557 | W33: =IFERROR(T33-S33,"") -> 6543 | X33: =IF(S33=0,"",T33/S33) -> 1.32715
D34: =(D30-D31)/D31 -> -0.081372012 | G34: 31 | H34: =IF(H33<$D$9,H33+1,"EOM") -> 45688 | I34: =TEXT(H34,"DDD") -> Fri | J34: 17000 | K34: 34 | L34: =IF(J34=0,"",J34/K34) -> 500 | M34: 4512 | N34: 21 | O34: =IF(M34=0,"",M34/N34) -> 214.85714 | P34: 2400 | Q34: 46 | R34: =IF(P34=0,"",P34/Q34) -> 52.173913 | S34: 20000 | T34: =IF(J34=0,"",J34+M34+P34) -> 23912 | U34: =IF(T34="","",K34+N34+Q34) -> 101 | V34: =IF(U34="","",T34/U34) -> 236.75248 | W34: =IFERROR(T34-S34,"") -> 3912 | X34: =IF(S34=0,"",T34/S34) -> 1.1956
G35: Totals | J35: =SUM(J4:J34) -> 398000 | K35: =SUM(K4:K34) -> 1216 | M35: =SUM(M4:M34) -> 180483 | N35: =SUM(N4:N34) -> 1213 | P35: =SUM(P4:P34) -> 73764 | Q35: =SUM(Q4:Q34) -> 1238 | S35: =SUM(S4:S34) -> 620000 | T35: =SUM(T4:T34) -> 652247 | U35: =SUM(U4:U34) -> 3667 | W35: =SUM(W4:W34) -> 32247

Sheet FEB
D2: DASHBOARD | G2: Daily Sales Report (Dine in, Take Away, Delivery) | S2: Consolidated
C3: Month | D3: February | G3: S.no | H3: Date | I3: Day | J3: Dine In sales | K3: Dine In Tickets | L3: APC / APT | M3: Take Away sales | N3: Take Away Tickets | O3: APC / APT | P3: Delivery sales | Q3: Delivery Tickets | R3: APC / APT | S3: Target Sales | T3: Total Sales | U3: Total Ticket | V3: APC / APT | W3: Target vs Achieved | X3: %
G4: 1 | H4: =D7 -> 45689 | I4: =TEXT(H4,"DDD") -> Sat | J4: 15000 | K4: 24 | L4: =IF(J4=0,"",J4/K4) -> 625 | M4: 7000 | N4: 35 | O4: =IF(M4=0,"",M4/N4) -> 200 | P4: 6000 | Q4: 36 | R4: =IF(P4=0,"",P4/Q4) -> 166.66667 | S4: 20000 | T4: =IF(J4=0,"",J4+M4+P4) -> 28000 | U4: =IF(T4="","",K4+N4+Q4) -> 95 | V4: =IF(U4="","",T4/U4) -> 294.73684 | W4: =IFERROR(T4-S4,"") -> 8000 | X4: =IF(S4=0,"",T4/S4) -> 1.4
C5: Year | D5: 2025 | G5: 2 | H5: =IF(H4<$D$9,H4+1,"EOM") -> 45690 | I5: =TEXT(H5,"DDD") -> Sun | J5: 12000 | K5: 45 | L5: =IF(J5=0,"",J5/K5) -> 266.66667 | M5: 5500 | N5: 50 | O5: =IF(M5=0,"",M5/N5) -> 110 | P5: 5321 | Q5: 34 | R5: =IF(P5=0,"",P5/Q5) -> 156.5 | S5: 20000 | T5: =IF(J5=0,"",J5+M5+P5) -> 22821 | U5: =IF(T5="","",K5+N5+Q5) -> 129 | V5: =IF(U5="","",T5/U5) -> 176.90698 | W5: =IFERROR(T5-S5,"") -> 2821 | X5: =IF(S5=0,"",T5/S5) -> 1.14105
G6: 3 | H6: =IF(H5<$D$9,H5+1,"EOM") -> 45691 | I6: =TEXT(H6,"DDD") -> Mon | J6: 14000 | K6: 46 | L6: =IF(J6=0,"",J6/K6) -> 304.34783 | M6: 5600 | N6: 40 | O6: =IF(M6=0,"",M6/N6) -> 140 | P6: 1200 | Q6: 24 | R6: =IF(P6=0,"",P6/Q6) -> 50 | S6: 20000 | T6: =IF(J6=0,"",J6+M6+P6) -> 20800 | U6: =IF(T6="","",K6+N6+Q6) -> 110 | V6: =IF(U6="","",T6/U6) -> 189.09091 | W6: =IFERROR(T6-S6,"") -> 800 | X6: =IF(S6=0,"",T6/S6) -> 1.04
C7: Start Date | D7: =DATEVALUE("1"& D3 & D5) -> 45689 | G7: 4 | H7: =IF(H6<$D$9,H6+1,"EOM") -> 45692 | I7: =TEXT(H7,"DDD") -> Tue | J7: 11000 | K7: 35 | L7: =IF(J7=0,"",J7/K7) -> 314.28571 | M7: 5800 | N7: 36 | O7: =IF(M7=0,"",M7/N7) -> 161.11111 | P7: 2200 | Q7: 45 | R7: =IF(P7=0,"",P7/Q7) -> 48.888889 | S7: 20000 | T7: =IF(J7=0,"",J7+M7+P7) -> 19000 | U7: =IF(T7="","",K7+N7+Q7) -> 116 | V7: =IF(U7="","",T7/U7) -> 163.7931 | W7: =IFERROR(T7-S7,"") -> -1000 | X7: =IF(S7=0,"",T7/S7) -> 0.95
G8: 5 | H8: =IF(H7<$D$9,H7+1,"EOM") -> 45693 | I8: =TEXT(H8,"DDD") -> Wed | J8: 10000 | K8: 50 | L8: =IF(J8=0,"",J8/K8) -> 200 | M8: 7100 | N8: 34 | O8: =IF(M8=0,"",M8/N8) -> 208.82353 | P8: 2415 | Q8: 46 | R8: =IF(P8=0,"",P8/Q8) -> 52.5 | S8: 20000 | T8: =IF(J8=0,"",J8+M8+P8) -> 19515 | U8: =IF(T8="","",K8+N8+Q8) -> 130 | V8: =IF(U8="","",T8/U8) -> 150.11538 | W8: =IFERROR(T8-S8,"") -> -485 | X8: =IF(S8=0,"",T8/S8) -> 0.97575
C9: End Date | D9: =EOMONTH(D7, 0) -> 45716 | G9: 6 | H9: =IF(H8<$D$9,H8+1,"EOM") -> 45694 | I9: =TEXT(H9,"DDD") -> Thu | J9: 16000 | K9: 40 | L9: =IF(J9=0,"",J9/K9) -> 400 | M9: 6500 | N9: 24 | O9: =IF(M9=0,"",M9/N9) -> 270.83333 | P9: 2561 | Q9: 35 | R9: =IF(P9=0,"",P9/Q9) -> 73.171429 | S9: 20000 | T9: =IF(J9=0,"",J9+M9+P9) -> 25061 | U9: =IF(T9="","",K9+N9+Q9) -> 99 | V9: =IF(U9="","",T9/U9) -> 253.14141 | W9: =IFERROR(T9-S9,"") -> 5061 | X9: =IF(S9=0,"",T9/S9) -> 1.25305
G10: 7 | H10: =IF(H9<$D$9,H9+1,"EOM") -> 45695 | I10: =TEXT(H10,"DDD") -> Fri | J10: 12000 | K10: 36 | L10: =IF(J10=0,"",J10/K10) -> 333.33333 | M10: 6200 | N10: 45 | O10: =IF(M10=0,"",M10/N10) -> 137.77778 | P10: 3214 | Q10: 50 | R10: =IF(P10=0,"",P10/Q10) -> 64.28 | S10: 20000 | T10: =IF(J10=0,"",J10+M10+P10) -> 21414 | U10: =IF(T10="","",K10+N10+Q10) -> 131 | V10: =IF(U10="","",T10/U10) -> 163.46565 | W10: =IFERROR(T10-S10,"") -> 1414 | X10: =IF(S10=0,"",T10/S10) -> 1.0707
C11: Total Days | D11: =COUNT(H4:H34) -> 28 | G11: 8 | H11: =IF(H10<$D$9,H10+1,"EOM") -> 45696 | I11: =TEXT(H11,"DDD") -> Sat | J11: 11000 | K11: 34 | L11: =IF(J11=0,"",J11/K11) -> 323.52941 | M11: 4500 | N11: 46 | O11: =IF(M11=0,"",M11/N11) -> 97.826087 | P11: 2315 | Q11: 40 | R11: =IF(P11=0,"",P11/Q11) -> 57.875 | S11: 20000 | T11: =IF(J11=0,"",J11+M11+P11) -> 17815 | U11: =IF(T11="","",K11+N11+Q11) -> 120 | V11: =IF(U11="","",T11/U11) -> 148.45833 | W11: =IFERROR(T11-S11,"") -> -2185 | X11: =IF(S11=0,"",T11/S11) -> 0.89075
G12: 9 | H12: =IF(H11<$D$9,H11+1,"EOM") -> 45697 | I12: =TEXT(H12,"DDD") -> Sun | J12: 15000 | K12: 24 | L12: =IF(J12=0,"",J12/K12) -> 625 | M12: 7200 | N12: 35 | O12: =IF(M12=0,"",M12/N12) -> 205.71429 | P12: 3524 | Q12: 36 | R12: =IF(P12=0,"",P12/Q12) -> 97.888889 | S12: 20000 | T12: =IF(J12=0,"",J12+M12+P12) -> 25724 | U12: =IF(T12="","",K12+N12+Q12) -> 95 | V12: =IF(U12="","",T12/U12) -> 270.77895 | W12: =IFERROR(T12-S12,"") -> 5724 | X12: =IF(S12=0,"",T12/S12) -> 1.2862
C13: Total Saturday | D13: =COUNTIF(I4:I34,"Sat") -> 4 | G13: 10 | H13: =IF(H12<$D$9,H12+1,"EOM") -> 45698 | I13: =TEXT(H13,"DDD") -> Mon | J13: 12000 | K13: 45 | L13: =IF(J13=0,"",J13/K13) -> 266.66667 | M13: 6900 | N13: 50 | O13: =IF(M13=0,"",M13/N13) -> 138 | P13: 3621 | Q13: 34 | R13: =IF(P13=0,"",P13/Q13) -> 106.5 | S13: 20000 | T13: =IF(J13=0,"",J13+M13+P13) -> 22521 | U13: =IF(T13="","",K13+N13+Q13) -> 129 | V13: =IF(U13="","",T13/U13) -> 174.5814 | W13: =IFERROR(T13-S13,"") -> 2521 | X13: =IF(S13=0,"",T13/S13) -> 1.12605
C14: Total Sunday | D14: =COUNTIF(I4:I34,"Sun") -> 4 | G14: 11 | H14: =IF(H13<$D$9,H13+1,"EOM") -> 45699 | I14: =TEXT(H14,"DDD") -> Tue | J14: 14000 | K14: 46 | L14: =IF(J14=0,"",J14/K14) -> 304.34783 | M14: 5900 | N14: 40 | O14: =IF(M14=0,"",M14/N14) -> 147.5 | P14: 1200 | Q14: 45 | R14: =IF(P14=0,"",P14/Q14) -> 26.666667 | S14: 20000 | T14: =IF(J14=0,"",J14+M14+P14) -> 21100 | U14: =IF(T14="","",K14+N14+Q14) -> 131 | V14: =IF(U14="","",T14/U14) -> 161.0687 | W14: =IFERROR(T14-S14,"") -> 1100 | X14: =IF(S14=0,"",T14/S14) -> 1.055
G15: 12 | H15: =IF(H14<$D$9,H14+1,"EOM") -> 45700 | I15: =TEXT(H15,"DDD") -> Wed | J15: 11000 | K15: 35 | L15: =IF(J15=0,"",J15/K15) -> 314.28571 | M15: 7500 | N15: 36 | O15: =IF(M15=0,"",M15/N15) -> 208.33333 | P15: 850 | Q15: 46 | R15: =IF(P15=0,"",P15/Q15) -> 18.478261 | S15: 20000 | T15: =IF(J15=0,"",J15+M15+P15) -> 19350 | U15: =IF(T15="","",K15+N15+Q15) -> 117 | V15: =IF(U15="","",T15/U15) -> 165.38462 | W15: =IFERROR(T15-S15,"") -> -650 | X15: =IF(S15=0,"",T15/S15) -> 0.9675
C16: Highest sales for the day | D16: =MAX(T4:T34) -> 28000 | G16: 13 | H16: =IF(H15<$D$9,H15+1,"EOM") -> 45701 | I16: =TEXT(H16,"DDD") -> Thu | J16: 10000 | K16: 50 | L16: =IF(J16=0,"",J16/K16) -> 200 | M16: 5800 | N16: 34 | O16: =IF(M16=0,"",M16/N16) -> 170.58824 | P16: 1421 | Q16: 35 | R16: =IF(P16=0,"",P16/Q16) -> 40.6 | S16: 20000 | T16: =IF(J16=0,"",J16+M16+P16) -> 17221 | U16: =IF(T16="","",K16+N16+Q16) -> 119 | V16: =IF(U16="","",T16/U16) -> 144.71429 | W16: =IFERROR(T16-S16,"") -> -2779 | X16: =IF(S16=0,"",T16/S16) -> 0.86105
G17: 14 | H17: =IF(H16<$D$9,H16+1,"EOM") -> 45702 | I17: =TEXT(H17,"DDD") -> Fri | J17: 16000 | K17: 40 | L17: =IF(J17=0,"",J17/K17) -> 400 | M17: 4500 | N17: 45 | O17: =IF(M17=0,"",M17/N17) -> 100 | P17: 1562 | Q17: 50 | R17: =IF(P17=0,"",P17/Q17) -> 31.24 | S17: 20000 | T17: =IF(J17=0,"",J17+M17+P17) -> 22062 | U17: =IF(T17="","",K17+N17+Q17) -> 135 | V17: =IF(U17="","",T17/U17) -> 163.42222 | W17: =IFERROR(T17-S17,"") -> 2062 | X17: =IF(S17=0,"",T17/S17) -> 1.1031
C18: Lowest sales for the day | D18: =MIN(T4:T34) -> 16300 | G18: 15 | H18: =IF(H17<$D$9,H17+1,"EOM") -> 45703 | I18: =TEXT(H18,"DDD") -> Sat | J18: 12000 | K18: 36 | L18: =IF(J18=0,"",J18/K18) -> 333.33333 | M18: 4900 | N18: 46 | O18: =IF(M18=0,"",M18/N18) -> 106.52174 | P18: 1900 | Q18: 40 | R18: =IF(P18=0,"",P18/Q18) -> 47.5 | S18: 20000 | T18: =IF(J18=0,"",J18+M18+P18) -> 18800 | U18: =IF(T18="","",K18+N18+Q18) -> 122 | V18: =IF(U18="","",T18/U18) -> 154.09836 | W18: =IFERROR(T18-S18,"") -> -1200 | X18: =IF(S18=0,"",T18/S18) -> 0.94
G19: 16 | H19: =IF(H18<$D$9,H18+1,"EOM") -> 45704 | I19: =TEXT(H19,"DDD") -> Sun | J19: 11000 | K19: 34 | L19: =IF(J19=0,"",J19/K19) -> 323.52941 | M19: 3200 | N19: 35 | O19: =IF(M19=0,"",M19/N19) -> 91.428571 | P19: 2100 | Q19: 36 | R19: =IF(P19=0,"",P19/Q19) -> 58.333333 | S19: 20000 | T19: =IF(J19=0,"",J19+M19+P19) -> 16300 | U19: =IF(T19="","",K19+N19+Q19) -> 105 | V19: =IF(U19="","",T19/U19) -> 155.2381 | W19: =IFERROR(T19-S19,"") -> -3700 | X19: =IF(S19=0,"",T19/S19) -> 0.815
C20: Target Achieved | D20: =IF(T35>S35,"Yes","No") -> Yes | G20: 17 | H20: =IF(H19<$D$9,H19+1,"EOM") -> 45705 | I20: =TEXT(H20,"DDD") -> Mon | J20: 15000 | K20: 24 | L20: =IF(J20=0,"",J20/K20) -> 625 | M20: 4600 | N20: 50 | O20: =IF(M20=0,"",M20/N20) -> 92 | P20: 2135 | Q20: 34 | R20: =IF(P20=0,"",P20/Q20) -> 62.794118 | S20: 20000 | T20: =IF(J20=0,"",J20+M20+P20) -> 21735 | U20: =IF(T20="","",K20+N20+Q20) -> 108 | V20: =IF(U20="","",T20/U20) -> 201.25 | W20: =IFERROR(T20-S20,"") -> 1735 | X20: =IF(S20=0,"",T20/S20) -> 1.08675
G21: 18 | H21: =IF(H20<$D$9,H20+1,"EOM") -> 45706 | I21: =TEXT(H21,"DDD") -> Tue | J21: 12000 | K21: 45 | L21: =IF(J21=0,"",J21/K21) -> 266.66667 | M21: 5600 | N21: 40 | O21: =IF(M21=0,"",M21/N21) -> 140 | P21: 2362 | Q21: 24 | R21: =IF(P21=0,"",P21/Q21) -> 98.416667 | S21: 20000 | T21: =IF(J21=0,"",J21+M21+P21) -> 19962 | U21: =IF(T21="","",K21+N21+Q21) -> 109 | V21: =IF(U21="","",T21/U21) -> 183.13761 | W21: =IFERROR(T21-S21,"") -> -38 | X21: =IF(S21=0,"",T21/S21) -> 0.9981
C22: Sales till date | D22: =T35 -> 652247 | G22: 19 | H22: =IF(H21<$D$9,H21+1,"EOM") -> 45707 | I22: =TEXT(H22,"DDD") -> Wed | J22: 14000 | K22: 46 | L22: =IF(J22=0,"",J22/K22) -> 304.34783 | M22: 4500 | N22: 36 | O22: =IF(M22=0,"",M22/N22) -> 125 | P22: 3521 | Q22: 45 | R22: =IF(P22=0,"",P22/Q22) -> 78.244444 | S22: 20000 | T22: =IF(J22=0,"",J22+M22+P22) -> 22021 | U22: =IF(T22="","",K22+N22+Q22) -> 127 | V22: =IF(U22="","",T22/U22) -> 173.3937 | W22: =IFERROR(T22-S22,"") -> 2021 | X22: =IF(S22=0,"",T22/S22) -> 1.10105
G23: 20 | H23: =IF(H22<$D$9,H22+1,"EOM") -> 45708 | I23: =TEXT(H23,"DDD") -> Thu | J23: 11000 | K23: 35 | L23: =IF(J23=0,"",J23/K23) -> 314.28571 | M23: 7500 | N23: 34 | O23: =IF(M23=0,"",M23/N23) -> 220.58824 | P23: 3254 | Q23: 46 | R23: =IF(P23=0,"",P23/Q23) -> 70.73913 | S23: 20000 | T23: =IF(J23=0,"",J23+M23+P23) -> 21754 | U23: =IF(T23="","",K23+N23+Q23) -> 115 | V23: =IF(U23="","",T23/U23) -> 189.16522 | W23: =IFERROR(T23-S23,"") -> 1754 | X23: =IF(S23=0,"",T23/S23) -> 1.0877
C24: Average sales | D24: =AVERAGE(T4:T34) -> 21040.226 | G24: 21 | H24: =IF(H23<$D$9,H23+1,"EOM") -> 45709 | I24: =TEXT(H24,"DDD") -> Fri | J24: 10000 | K24: 50 | L24: =IF(J24=0,"",J24/K24) -> 200 | M24: 5900 | N24: 24 | O24: =IF(M24=0,"",M24/N24) -> 245.83333 | P24: 2651 | Q24: 35 | R24: =IF(P24=0,"",P24/Q24) -> 75.742857 | S24: 20000 | T24: =IF(J24=0,"",J24+M24+P24) -> 18551 | U24: =IF(T24="","",K24+N24+Q24) -> 109 | V24: =IF(U24="","",T24/U24) -> 170.19266 | W24: =IFERROR(T24-S24,"") -> -1449 | X24: =IF(S24=0,"",T24/S24) -> 0.92755
G25: 22 | H25: =IF(H24<$D$9,H24+1,"EOM") -> 45710 | I25: =TEXT(H25,"DDD") -> Sat | J25: 16000 | K25: 40 | L25: =IF(J25=0,"",J25/K25) -> 400 | M25: 6200 | N25: 45 | O25: =IF(M25=0,"",M25/N25) -> 137.77778 | P25: 2548 | Q25: 50 | R25: =IF(P25=0,"",P25/Q25) -> 50.96 | S25: 20000 | T25: =IF(J25=0,"",J25+M25+P25) -> 24748 | U25: =IF(T25="","",K25+N25+Q25) -> 135 | V25: =IF(U25="","",T25/U25) -> 183.31852 | W25: =IFERROR(T25-S25,"") -> 4748 | X25: =IF(S25=0,"",T25/S25) -> 1.2374
C26: Dine in sales | D26: =J35 -> 398000 | G26: 23 | H26: =IF(H25<$D$9,H25+1,"EOM") -> 45711 | I26: =TEXT(H26,"DDD") -> Sun | J26: 12000 | K26: 36 | L26: =IF(J26=0,"",J26/K26) -> 333.33333 | M26: 6321 | N26: 46 | O26: =IF(M26=0,"",M26/N26) -> 137.41304 | P26: 950 | Q26: 40 | R26: =IF(P26=0,"",P26/Q26) -> 23.75 | S26: 20000 | T26: =IF(J26=0,"",J26+M26+P26) -> 19271 | U26: =IF(T26="","",K26+N26+Q26) -> 122 | V26: =IF(U26="","",T26/U26) -> 157.95902 | W26: =IFERROR(T26-S26,"") -> -729 | X26: =IF(S26=0,"",T26/S26) -> 0.96355
C27: Take away sales | D27: =M35 -> 180483 | G27: 24 | H27: =IF(H26<$D$9,H26+1,"EOM") -> 45712 | I27: =TEXT(H27,"DDD") -> Mon | J27: 11000 | K27: 34 | L27: =IF(J27=0,"",J27/K27) -> 323.52941 | M27: 5621 | N27: 35 | O27: =IF(M27=0,"",M27/N27) -> 160.6 | P27: 1254 | Q27: 36 | R27: =IF(P27=0,"",P27/Q27) -> 34.833333 | S27: 20000 | T27: =IF(J27=0,"",J27+M27+P27) -> 17875 | U27: =IF(T27="","",K27+N27+Q27) -> 105 | V27: =IF(U27="","",T27/U27) -> 170.2381 | W27: =IFERROR(T27-S27,"") -> -2125 | X27: =IF(S27=0,"",T27/S27) -> 0.89375
C28: Delivery sales | D28: =P35 -> 73764 | G28: 25 | H28: =IF(H27<$D$9,H27+1,"EOM") -> 45713 | I28: =TEXT(H28,"DDD") -> Tue | J28: 11000 | K28: 45 | L28: =IF(J28=0,"",J28/K28) -> 244.44444 | M28: 4856 | N28: 50 | O28: =IF(M28=0,"",M28/N28) -> 97.12 | P28: 1456 | Q28: 34 | R28: =IF(P28=0,"",P28/Q28) -> 42.823529 | S28: 20000 | T28: =IF(J28=0,"",J28+M28+P28) -> 17312 | U28: =IF(T28="","",K28+N28+Q28) -> 129 | V28: =IF(U28="","",T28/U28) -> 134.20155 | W28: =IFERROR(T28-S28,"") -> -2688 | X28: =IF(S28=0,"",T28/S28) -> 0.8656
G29: 26 | H29: =IF(H28<$D$9,H28+1,"EOM") -> 45714 | I29: =TEXT(H29,"DDD") -> Wed | J29: 10000 | K29: 46 | L29: =IF(J29=0,"",J29/K29) -> 217.3913 | M29: 5421 | N29: 40 | O29: =IF(M29=0,"",M29/N29) -> 135.525 | P29: 2540 | Q29: 45 | R29: =IF(P29=0,"",P29/Q29) -> 56.444444 | S29: 20000 | T29: =IF(J29=0,"",J29+M29+P29) -> 17961 | U29: =IF(T29="","",K29+N29+Q29) -> 131 | V29: =IF(U29="","",T29/U29) -> 137.10687 | W29: =IFERROR(T29-S29,"") -> -2039 | X29: =IF(S29=0,"",T29/S29) -> 0.89805
C30: Total sales | D30: =SUM(D26:D28) -> 652247 | G30: 27 | H30: =IF(H29<$D$9,H29+1,"EOM") -> 45715 | I30: =TEXT(H30,"DDD") -> Thu | J30: 16000 | K30: 35 | L30: =IF(J30=0,"",J30/K30) -> 457.14286 | M30: 5962 | N30: 36 | O30: =IF(M30=0,"",M30/N30) -> 165.61111 | P30: 2632 | Q30: 46 | R30: =IF(P30=0,"",P30/Q30) -> 57.217391 | S30: 20000 | T30: =IF(J30=0,"",J30+M30+P30) -> 24594 | U30: =IF(T30="","",K30+N30+Q30) -> 117 | V30: =IF(U30="","",T30/U30) -> 210.20513 | W30: =IFERROR(T30-S30,"") -> 4594 | X30: =IF(S30=0,"",T30/S30) -> 1.2297
C31: last year sales | D31: 710023 | G31: 28 | H31: =IF(H30<$D$9,H30+1,"EOM") -> 45716 | I31: =TEXT(H31,"DDD") -> Fri | J31: 12000 | K31: 50 | L31: =IF(J31=0,"",J31/K31) -> 240 | M31: 6521 | N31: 34 | O31: =IF(M31=0,"",M31/N31) -> 191.79412 | P31: 1100 | Q31: 35 | R31: =IF(P31=0,"",P31/Q31) -> 31.428571 | S31: 20000 | T31: =IF(J31=0,"",J31+M31+P31) -> 19621 | U31: =IF(T31="","",K31+N31+Q31) -> 119 | V31: =IF(U31="","",T31/U31) -> 164.88235 | W31: =IFERROR(T31-S31,"") -> -379 | X31: =IF(S31=0,"",T31/S31) -> 0.98105
G32: 29 | H32: =IF(H31<$D$9,H31+1,"EOM") -> EOM | I32: =TEXT(H32,"DDD") -> EOM | J32: 11000 | K32: 40 | L32: =IF(J32=0,"",J32/K32) -> 275 | M32: 6321 | N32: 45 | O32: =IF(M32=0,"",M32/N32) -> 140.46667 | P32: 1562 | Q32: 50 | R32: =IF(P32=0,"",P32/Q32) -> 31.24 | S32: 20000 | T32: =IF(J32=0,"",J32+M32+P32) -> 18883 | U32: =IF(T32="","",K32+N32+Q32) -> 135 | V32: =IF(U32="","",T32/U32) -> 139.87407 | W32: =IFERROR(T32-S32,"") -> -1117 | X32: =IF(S32=0,"",T32/S32) -> 0.94415
C33: Growth | D33: =D30-D31 -> -57776 | G33: 30 | H33: =IF(H32<$D$9,H32+1,"EOM") -> EOM | I33: =TEXT(H33,"DDD") -> EOM | J33: 18000 | K33: 36 | L33: =IF(J33=0,"",J33/K33) -> 500 | M33: 6548 | N33: 46 | O33: =IF(M33=0,"",M33/N33) -> 142.34783 | P33: 1995 | Q33: 40 | R33: =IF(P33=0,"",P33/Q33) -> 49.875 | S33: 20000 | T33: =IF(J33=0,"",J33+M33+P33) -> 26543 | U33: =IF(T33="","",K33+N33+Q33) -> 122 | V33: =IF(U33="","",T33/U33) -> 217.56557 | W33: =IFERROR(T33-S33,"") -> 6543 | X33: =IF(S33=0,"",T33/S33) -> 1.32715
D34: =(D30-D31)/D31 -> -0.081372012 | G34: 31 | H34: =IF(H33<$D$9,H33+1,"EOM") -> EOM | I34: =TEXT(H34,"DDD") -> EOM | J34: 17000 | K34: 34 | L34: =IF(J34=0,"",J34/K34) -> 500 | M34: 4512 | N34: 21 | O34: =IF(M34=0,"",M34/N34) -> 214.85714 | P34: 2400 | Q34: 46 | R34: =IF(P34=0,"",P34/Q34) -> 52.173913 | S34: 20000 | T34: =IF(J34=0,"",J34+M34+P34) -> 23912 | U34: =IF(T34="","",K34+N34+Q34) -> 101 | V34: =IF(U34="","",T34/U34) -> 236.75248 | W34: =IFERROR(T34-S34,"") -> 3912 | X34: =IF(S34=0,"",T34/S34) -> 1.1956
G35: Totals | J35: =SUM(J4:J34) -> 398000 | K35: =SUM(K4:K34) -> 1216 | M35: =SUM(M4:M34) -> 180483 | N35: =SUM(N4:N34) -> 1213 | P35: =SUM(P4:P34) -> 73764 | Q35: =SUM(Q4:Q34) -> 1238 | S35: =SUM(S4:S34) -> 620000 | T35: =SUM(T4:T34) -> 652247 | U35: =SUM(U4:U34) -> 3667 | W35: =SUM(W4:W34) -> 32247

Sheet MAR
D2: DASHBOARD | G2: Daily Sales Report (Dine in, Take Away, Delivery) | S2: Consolidated
C3: Month | D3: March | G3: S.no | H3: Date | I3: Day | J3: Dine In sales | K3: Dine In Tickets | L3: APC / APT | M3: Take Away sales | N3: Take Away Tickets | O3: APC / APT | P3: Delivery sales | Q3: Delivery Tickets | R3: APC / APT | S3: Target Sales | T3: Total Sales | U3: Total Ticket | V3: APC / APT | W3: Target vs Achieved | X3: %
G4: 1 | H4: =D7 -> 45717 | I4: =TEXT(H4,"DDD") -> Sat | J4: 15000 | K4: 24 | L4: =IF(J4=0,"",J4/K4) -> 625 | M4: 7000 | N4: 35 | O4: =IF(M4=0,"",M4/N4) -> 200 | P4: 6000 | Q4: 36 | R4: =IF(P4=0,"",P4/Q4) -> 166.66667 | S4: 20000 | T4: =IF(J4=0,"",J4+M4+P4) -> 28000 | U4: =IF(T4="","",K4+N4+Q4) -> 95 | V4: =IF(U4="","",T4/U4) -> 294.73684 | W4: =IFERROR(T4-S4,"") -> 8000 | X4: =IF(S4=0,"",T4/S4) -> 1.4
C5: Year | D5: 2025 | G5: 2 | H5: =IF(H4<$D$9,H4+1,"EOM") -> 45718 | I5: =TEXT(H5,"DDD") -> Sun | J5: 12000 | K5: 45 | L5: =IF(J5=0,"",J5/K5) -> 266.66667 | M5: 5500 | N5: 50 | O5: =IF(M5=0,"",M5/N5) -> 110 | P5: 5321 | Q5: 34 | R5: =IF(P5=0,"",P5/Q5) -> 156.5 | S5: 20000 | T5: =IF(J5=0,"",J5+M5+P5) -> 22821 | U5: =IF(T5="","",K5+N5+Q5) -> 129 | V5: =IF(U5="","",T5/U5) -> 176.90698 | W5: =IFERROR(T5-S5,"") -> 2821 | X5: =IF(S5=0,"",T5/S5) -> 1.14105
G6: 3 | H6: =IF(H5<$D$9,H5+1,"EOM") -> 45719 | I6: =TEXT(H6,"DDD") -> Mon | J6: 14000 | K6: 46 | L6: =IF(J6=0,"",J6/K6) -> 304.34783 | M6: 5600 | N6: 40 | O6: =IF(M6=0,"",M6/N6) -> 140 | P6: 1200 | Q6: 24 | R6: =IF(P6=0,"",P6/Q6) -> 50 | S6: 20000 | T6: =IF(J6=0,"",J6+M6+P6) -> 20800 | U6: =IF(T6="","",K6+N6+Q6) -> 110 | V6: =IF(U6="","",T6/U6) -> 189.09091 | W6: =IFERROR(T6-S6,"") -> 800 | X6: =IF(S6=0,"",T6/S6) -> 1.04
C7: Start Date | D7: =DATEVALUE("1"& D3 & D5) -> 45717 | G7: 4 | H7: =IF(H6<$D$9,H6+1,"EOM") -> 45720 | I7: =TEXT(H7,"DDD") -> Tue | J7: 11000 | K7: 35 | L7: =IF(J7=0,"",J7/K7) -> 314.28571 | M7: 5800 | N7: 36 | O7: =IF(M7=0,"",M7/N7) -> 161.11111 | P7: 2200 | Q7: 45 | R7: =IF(P7=0,"",P7/Q7) -> 48.888889 | S7: 20000 | T7: =IF(J7=0,"",J7+M7+P7) -> 19000 | U7: =IF(T7="","",K7+N7+Q7) -> 116 | V7: =IF(U7="","",T7/U7) -> 163.7931 | W7: =IFERROR(T7-S7,"") -> -1000 | X7: =IF(S7=0,"",T7/S7) -> 0.95
G8: 5 | H8: =IF(H7<$D$9,H7+1,"EOM") -> 45721 | I8: =TEXT(H8,"DDD") -> Wed | J8: 10000 | K8: 50 | L8: =IF(J8=0,"",J8/K8) -> 200 | M8: 7100 | N8: 34 | O8: =IF(M8=0,"",M8/N8) -> 208.82353 | P8: 2415 | Q8: 46 | R8: =IF(P8=0,"",P8/Q8) -> 52.5 | S8: 20000 | T8: =IF(J8=0,"",J8+M8+P8) -> 19515 | U8: =IF(T8="","",K8+N8+Q8) -> 130 | V8: =IF(U8="","",T8/U8) -> 150.11538 | W8: =IFERROR(T8-S8,"") -> -485 | X8: =IF(S8=0,"",T8/S8) -> 0.97575
C9: End Date | D9: =EOMONTH(D7, 0) -> 45747 | G9: 6 | H9: =IF(H8<$D$9,H8+1,"EOM") -> 45722 | I9: =TEXT(H9,"DDD") -> Thu | J9: 16000 | K9: 40 | L9: =IF(J9=0,"",J9/K9) -> 400 | M9: 6500 | N9: 24 | O9: =IF(M9=0,"",M9/N9) -> 270.83333 | P9: 2561 | Q9: 35 | R9: =IF(P9=0,"",P9/Q9) -> 73.171429 | S9: 20000 | T9: =IF(J9=0,"",J9+M9+P9) -> 25061 | U9: =IF(T9="","",K9+N9+Q9) -> 99 | V9: =IF(U9="","",T9/U9) -> 253.14141 | W9: =IFERROR(T9-S9,"") -> 5061 | X9: =IF(S9=0,"",T9/S9) -> 1.25305
G10: 7 | H10: =IF(H9<$D$9,H9+1,"EOM") -> 45723 | I10: =TEXT(H10,"DDD") -> Fri | J10: 12000 | K10: 36 | L10: =IF(J10=0,"",J10/K10) -> 333.33333 | M10: 6200 | N10: 45 | O10: =IF(M10=0,"",M10/N10) -> 137.77778 | P10: 3214 | Q10: 50 | R10: =IF(P10=0,"",P10/Q10) -> 64.28 | S10: 20000 | T10: =IF(J10=0,"",J10+M10+P10) -> 21414 | U10: =IF(T10="","",K10+N10+Q10) -> 131 | V10: =IF(U10="","",T10/U10) -> 163.46565 | W10: =IFERROR(T10-S10,"") -> 1414 | X10: =IF(S10=0,"",T10/S10) -> 1.0707
C11: Total Days | D11: =COUNT(H4:H34) -> 31 | G11: 8 | H11: =IF(H10<$D$9,H10+1,"EOM") -> 45724 | I11: =TEXT(H11,"DDD") -> Sat | J11: 11000 | K11: 34 | L11: =IF(J11=0,"",J11/K11) -> 323.52941 | M11: 4500 | N11: 46 | O11: =IF(M11=0,"",M11/N11) -> 97.826087 | P11: 2315 | Q11: 40 | R11: =IF(P11=0,"",P11/Q11) -> 57.875 | S11: 20000 | T11: =IF(J11=0,"",J11+M11+P11) -> 17815 | U11: =IF(T11="","",K11+N11+Q11) -> 120 | V11: =IF(U11="","",T11/U11) -> 148.45833 | W11: =IFERROR(T11-S11,"") -> -2185 | X11: =IF(S11=0,"",T11/S11) -> 0.89075
G12: 9 | H12: =IF(H11<$D$9,H11+1,"EOM") -> 45725 | I12: =TEXT(H12,"DDD") -> Sun | J12: 15000 | K12: 24 | L12: =IF(J12=0,"",J12/K12) -> 625 | M12: 7200 | N12: 35 | O12: =IF(M12=0,"",M12/N12) -> 205.71429 | P12: 3524 | Q12: 36 | R12: =IF(P12=0,"",P12/Q12) -> 97.888889 | S12: 20000 | T12: =IF(J12=0,"",J12+M12+P12) -> 25724 | U12: =IF(T12="","",K12+N12+Q12) -> 95 | V12: =IF(U12="","",T12/U12) -> 270.77895 | W12: =IFERROR(T12-S12,"") -> 5724 | X12: =IF(S12=0,"",T12/S12) -> 1.2862
C13: Total Saturday | D13: =COUNTIF(I4:I34,"Sat") -> 5 | G13: 10 | H13: =IF(H12<$D$9,H12+1,"EOM") -> 45726 | I13: =TEXT(H13,"DDD") -> Mon | J13: 12000 | K13: 45 | L13: =IF(J13=0,"",J13/K13) -> 266.66667 | M13: 6900 | N13: 50 | O13: =IF(M13=0,"",M13/N13) -> 138 | P13: 3621 | Q13: 34 | R13: =IF(P13=0,"",P13/Q13) -> 106.5 | S13: 20000 | T13: =IF(J13=0,"",J13+M13+P13) -> 22521 | U13: =IF(T13="","",K13+N13+Q13) -> 129 | V13: =IF(U13="","",T13/U13) -> 174.5814 | W13: =IFERROR(T13-S13,"") -> 2521 | X13: =IF(S13=0,"",T13/S13) -> 1.12605
C14: Total Sunday | D14: =COUNTIF(I4:I34,"Sun") -> 5 | G14: 11 | H14: =IF(H13<$D$9,H13+1,"EOM") -> 45727 | I14: =TEXT(H14,"DDD") -> Tue | J14: 14000 | K14: 46 | L14: =IF(J14=0,"",J14/K14) -> 304.34783 | M14: 5900 | N14: 40 | O14: =IF(M14=0,"",M14/N14) -> 147.5 | P14: 1200 | Q14: 45 | R14: =IF(P14=0,"",P14/Q14) -> 26.666667 | S14: 20000 | T14: =IF(J14=0,"",J14+M14+P14) -> 21100 | U14: =IF(T14="","",K14+N14+Q14) -> 131 | V14: =IF(U14="","",T14/U14) -> 161.0687 | W14: =IFERROR(T14-S14,"") -> 1100 | X14: =IF(S14=0,"",T14/S14) -> 1.055
G15: 12 | H15: =IF(H14<$D$9,H14+1,"EOM") -> 45728 | I15: =TEXT(H15,"DDD") -> Wed | J15: 11000 | K15: 35 | L15: =IF(J15=0,"",J15/K15) -> 314.28571 | M15: 7500 | N15: 36 | O15: =IF(M15=0,"",M15/N15) -> 208.33333 | P15: 850 | Q15: 46 | R15: =IF(P15=0,"",P15/Q15) -> 18.478261 | S15: 20000 | T15: =IF(J15=0,"",J15+M15+P15) -> 19350 | U15: =IF(T15="","",K15+N15+Q15) -> 117 | V15: =IF(U15="","",T15/U15) -> 165.38462 | W15: =IFERROR(T15-S15,"") -> -650 | X15: =IF(S15=0,"",T15/S15) -> 0.9675
C16: Highest sales for the day | D16: =MAX(T4:T34) -> 28000 | G16: 13 | H16: =IF(H15<$D$9,H15+1,"EOM") -> 45729 | I16: =TEXT(H16,"DDD") -> Thu | J16: 10000 | K16: 50 | L16: =IF(J16=0,"",J16/K16) -> 200 | M16: 5800 | N16: 34 | O16: =IF(M16=0,"",M16/N16) -> 170.58824 | P16: 1421 | Q16: 35 | R16: =IF(P16=0,"",P16/Q16) -> 40.6 | S16: 20000 | T16: =IF(J16=0,"",J16+M16+P16) -> 17221 | U16: =IF(T16="","",K16+N16+Q16) -> 119 | V16: =IF(U16="","",T16/U16) -> 144.71429 | W16: =IFERROR(T16-S16,"") -> -2779 | X16: =IF(S16=0,"",T16/S16) -> 0.86105
G17: 14 | H17: =IF(H16<$D$9,H16+1,"EOM") -> 45730 | I17: =TEXT(H17,"DDD") -> Fri | J17: 16000 | K17: 40 | L17: =IF(J17=0,"",J17/K17) -> 400 | M17: 4500 | N17: 45 | O17: =IF(M17=0,"",M17/N17) -> 100 | P17: 1562 | Q17: 50 | R17: =IF(P17=0,"",P17/Q17) -> 31.24 | S17: 20000 | T17: =IF(J17=0,"",J17+M17+P17) -> 22062 | U17: =IF(T17="","",K17+N17+Q17) -> 135 | V17: =IF(U17="","",T17/U17) -> 163.42222 | W17: =IFERROR(T17-S17,"") -> 2062 | X17: =IF(S17=0,"",T17/S17) -> 1.1031
C18: Lowest sales for the day | D18: =MIN(T4:T34) -> 16300 | G18: 15 | H18: =IF(H17<$D$9,H17+1,"EOM") -> 45731 | I18: =TEXT(H18,"DDD") -> Sat | J18: 12000 | K18: 36 | L18: =IF(J18=0,"",J18/K18) -> 333.33333 | M18: 4900 | N18: 46 | O18: =IF(M18=0,"",M18/N18) -> 106.52174 | P18: 1900 | Q18: 40 | R18: =IF(P18=0,"",P18/Q18) -> 47.5 | S18: 20000 | T18: =IF(J18=0,"",J18+M18+P18) -> 18800 | U18: =IF(T18="","",K18+N18+Q18) -> 122 | V18: =IF(U18="","",T18/U18) -> 154.09836 | W18: =IFERROR(T18-S18,"") -> -1200 | X18: =IF(S18=0,"",T18/S18) -> 0.94
G19: 16 | H19: =IF(H18<$D$9,H18+1,"EOM") -> 45732 | I19: =TEXT(H19,"DDD") -> Sun | J19: 11000 | K19: 34 | L19: =IF(J19=0,"",J19/K19) -> 323.52941 | M19: 3200 | N19: 35 | O19: =IF(M19=0,"",M19/N19) -> 91.428571 | P19: 2100 | Q19: 36 | R19: =IF(P19=0,"",P19/Q19) -> 58.333333 | S19: 20000 | T19: =IF(J19=0,"",J19+M19+P19) -> 16300 | U19: =IF(T19="","",K19+N19+Q19) -> 105 | V19: =IF(U19="","",T19/U19) -> 155.2381 | W19: =IFERROR(T19-S19,"") -> -3700 | X19: =IF(S19=0,"",T19/S19) -> 0.815
C20: Target Achieved | D20: =IF(T35>S35,"Yes","No") -> Yes | G20: 17 | H20: =IF(H19<$D$9,H19+1,"EOM") -> 45733 | I20: =TEXT(H20,"DDD") -> Mon | J20: 15000 | K20: 24 | L20: =IF(J20=0,"",J20/K20) -> 625 | M20: 4600 | N20: 50 | O20: =IF(M20=0,"",M20/N20) -> 92 | P20: 2135 | Q20: 34 | R20: =IF(P20=0,"",P20/Q20) -> 62.794118 | S20: 20000 | T20: =IF(J20=0,"",J20+M20+P20) -> 21735 | U20: =IF(T20="","",K20+N20+Q20) -> 108 | V20: =IF(U20="","",T20/U20) -> 201.25 | W20: =IFERROR(T20-S20,"") -> 1735 | X20: =IF(S20=0,"",T20/S20) -> 1.08675
G21: 18 | H21: =IF(H20<$D$9,H20+1,"EOM") -> 45734 | I21: =TEXT(H21,"DDD") -> Tue | J21: 12000 | K21: 45 | L21: =IF(J21=0,"",J21/K21) -> 266.66667 | M21: 5600 | N21: 40 | O21: =IF(M21=0,"",M21/N21) -> 140 | P21: 2362 | Q21: 24 | R21: =IF(P21=0,"",P21/Q21) -> 98.416667 | S21: 20000 | T21: =IF(J21=0,"",J21+M21+P21) -> 19962 | U21: =IF(T21="","",K21+N21+Q21) -> 109 | V21: =IF(U21="","",T21/U21) -> 183.13761 | W21: =IFERROR(T21-S21,"") -> -38 | X21: =IF(S21=0,"",T21/S21) -> 0.9981
C22: Sales till date | D22: =T35 -> 652247 | G22: 19 | H22: =IF(H21<$D$9,H21+1,"EOM") -> 45735 | I22: =TEXT(H22,"DDD") -> Wed | J22: 14000 | K22: 46 | L22: =IF(J22=0,"",J22/K22) -> 304.34783 | M22: 4500 | N22: 36 | O22: =IF(M22=0,"",M22/N22) -> 125 | P22: 3521 | Q22: 45 | R22: =IF(P22=0,"",P22/Q22) -> 78.244444 | S22: 20000 | T22: =IF(J22=0,"",J22+M22+P22) -> 22021 | U22: =IF(T22="","",K22+N22+Q22) -> 127 | V22: =IF(U22="","",T22/U22) -> 173.3937 | W22: =IFERROR(T22-S22,"") -> 2021 | X22: =IF(S22=0,"",T22/S22) -> 1.10105
G23: 20 | H23: =IF(H22<$D$9,H22+1,"EOM") -> 45736 | I23: =TEXT(H23,"DDD") -> Thu | J23: 11000 | K23: 35 | L23: =IF(J23=0,"",J23/K23) -> 314.28571 | M23: 7500 | N23: 34 | O23: =IF(M23=0,"",M23/N23) -> 220.58824 | P23: 3254 | Q23: 46 | R23: =IF(P23=0,"",P23/Q23) -> 70.73913 | S23: 20000 | T23: =IF(J23=0,"",J23+M23+P23) -> 21754 | U23: =IF(T23="","",K23+N23+Q23) -> 115 | V23: =IF(U23="","",T23/U23) -> 189.16522 | W23: =IFERROR(T23-S23,"") -> 1754 | X23: =IF(S23=0,"",T23/S23) -> 1.0877
C24: Average sales | D24: =AVERAGE(T4:T34) -> 21040.226 | G24: 21 | H24: =IF(H23<$D$9,H23+1,"EOM") -> 45737 | I24: =TEXT(H24,"DDD") -> Fri | J24: 10000 | K24: 50 | L24: =IF(J24=0,"",J24/K24) -> 200 | M24: 5900 | N24: 24 | O24: =IF(M24=0,"",M24/N24) -> 245.83333 | P24: 2651 | Q24: 35 | R24: =IF(P24=0,"",P24/Q24) -> 75.742857 | S24: 20000 | T24: =IF(J24=0,"",J24+M24+P24) -> 18551 | U24: =IF(T24="","",K24+N24+Q24) -> 109 | V24: =IF(U24="","",T24/U24) -> 170.19266 | W24: =IFERROR(T24-S24,"") -> -1449 | X24: =IF(S24=0,"",T24/S24) -> 0.92755
G25: 22 | H25: =IF(H24<$D$9,H24+1,"EOM") -> 45738 | I25: =TEXT(H25,"DDD") -> Sat | J25: 16000 | K25: 40 | L25: =IF(J25=0,"",J25/K25) -> 400 | M25: 6200 | N25: 45 | O25: =IF(M25=0,"",M25/N25) -> 137.77778 | P25: 2548 | Q25: 50 | R25: =IF(P25=0,"",P25/Q25) -> 50.96 | S25: 20000 | T25: =IF(J25=0,"",J25+M25+P25) -> 24748 | U25: =IF(T25="","",K25+N25+Q25) -> 135 | V25: =IF(U25="","",T25/U25) -> 183.31852 | W25: =IFERROR(T25-S25,"") -> 4748 | X25: =IF(S25=0,"",T25/S25) -> 1.2374
C26: Dine in sales | D26: =J35 -> 398000 | G26: 23 | H26: =IF(H25<$D$9,H25+1,"EOM") -> 45739 | I26: =TEXT(H26,"DDD") -> Sun | J26: 12000 | K26: 36 | L26: =IF(J26=0,"",J26/K26) -> 333.33333 | M26: 6321 | N26: 46 | O26: =IF(M26=0,"",M26/N26) -> 137.41304 | P26: 950 | Q26: 40 | R26: =IF(P26=0,"",P26/Q26) -> 23.75 | S26: 20000 | T26: =IF(J26=0,"",J26+M26+P26) -> 19271 | U26: =IF(T26="","",K26+N26+Q26) -> 122 | V26: =IF(U26="","",T26/U26) -> 157.95902 | W26: =IFERROR(T26-S26,"") -> -729 | X26: =IF(S26=0,"",T26/S26) -> 0.96355
C27: Take away sales | D27: =M35 -> 180483 | G27: 24 | H27: =IF(H26<$D$9,H26+1,"EOM") -> 45740 | I27: =TEXT(H27,"DDD") -> Mon | J27: 11000 | K27: 34 | L27: =IF(J27=0,"",J27/K27) -> 323.52941 | M27: 5621 | N27: 35 | O27: =IF(M27=0,"",M27/N27) -> 160.6 | P27: 1254 | Q27: 36 | R27: =IF(P27=0,"",P27/Q27) -> 34.833333 | S27: 20000 | T27: =IF(J27=0,"",J27+M27+P27) -> 17875 | U27: =IF(T27="","",K27+N27+Q27) -> 105 | V27: =IF(U27="","",T27/U27) -> 170.2381 | W27: =IFERROR(T27-S27,"") -> -2125 | X27: =IF(S27=0,"",T27/S27) -> 0.89375
C28: Delivery sales | D28: =P35 -> 73764 | G28: 25 | H28: =IF(H27<$D$9,H27+1,"EOM") -> 45741 | I28: =TEXT(H28,"DDD") -> Tue | J28: 11000 | K28: 45 | L28: =IF(J28=0,"",J28/K28) -> 244.44444 | M28: 4856 | N28: 50 | O28: =IF(M28=0,"",M28/N28) -> 97.12 | P28: 1456 | Q28: 34 | R28: =IF(P28=0,"",P28/Q28) -> 42.823529 | S28: 20000 | T28: =IF(J28=0,"",J28+M28+P28) -> 17312 | U28: =IF(T28="","",K28+N28+Q28) -> 129 | V28: =IF(U28="","",T28/U28) -> 134.20155 | W28: =IFERROR(T28-S28,"") -> -2688 | X28: =IF(S28=0,"",T28/S28) -> 0.8656
G29: 26 | H29: =IF(H28<$D$9,H28+1,"EOM") -> 45742 | I29: =TEXT(H29,"DDD") -> Wed | J29: 10000 | K29: 46 | L29: =IF(J29=0,"",J29/K29) -> 217.3913 | M29: 5421 | N29: 40 | O29: =IF(M29=0,"",M29/N29) -> 135.525 | P29: 2540 | Q29: 45 | R29: =IF(P29=0,"",P29/Q29) -> 56.444444 | S29: 20000 | T29: =IF(J29=0,"",J29+M29+P29) -> 17961 | U29: =IF(T29="","",K29+N29+Q29) -> 131 | V29: =IF(U29="","",T29/U29) -> 137.10687 | W29: =IFERROR(T29-S29,"") -> -2039 | X29: =IF(S29=0,"",T29/S29) -> 0.89805
C30: Total sales | D30: =SUM(D26:D28) -> 652247 | G30: 27 | H30: =IF(H29<$D$9,H29+1,"EOM") -> 45743 | I30: =TEXT(H30,"DDD") -> Thu | J30: 16000 | K30: 35 | L30: =IF(J30=0,"",J30/K30) -> 457.14286 | M30: 5962 | N30: 36 | O30: =IF(M30=0,"",M30/N30) -> 165.61111 | P30: 2632 | Q30: 46 | R30: =IF(P30=0,"",P30/Q30) -> 57.217391 | S30: 20000 | T30: =IF(J30=0,"",J30+M30+P30) -> 24594 | U30: =IF(T30="","",K30+N30+Q30) -> 117 | V30: =IF(U30="","",T30/U30) -> 210.20513 | W30: =IFERROR(T30-S30,"") -> 4594 | X30: =IF(S30=0,"",T30/S30) -> 1.2297
C31: last year sales | D31: 710023 | G31: 28 | H31: =IF(H30<$D$9,H30+1,"EOM") -> 45744 | I31: =TEXT(H31,"DDD") -> Fri | J31: 12000 | K31: 50 | L31: =IF(J31=0,"",J31/K31) -> 240 | M31: 6521 | N31: 34 | O31: =IF(M31=0,"",M31/N31) -> 191.79412 | P31: 1100 | Q31: 35 | R31: =IF(P31=0,"",P31/Q31) -> 31.428571 | S31: 20000 | T31: =IF(J31=0,"",J31+M31+P31) -> 19621 | U31: =IF(T31="","",K31+N31+Q31) -> 119 | V31: =IF(U31="","",T31/U31) -> 164.88235 | W31: =IFERROR(T31-S31,"") -> -379 | X31: =IF(S31=0,"",T31/S31) -> 0.98105
G32: 29 | H32: =IF(H31<$D$9,H31+1,"EOM") -> 45745 | I32: =TEXT(H32,"DDD") -> Sat | J32: 11000 | K32: 40 | L32: =IF(J32=0,"",J32/K32) -> 275 | M32: 6321 | N32: 45 | O32: =IF(M32=0,"",M32/N32) -> 140.46667 | P32: 1562 | Q32: 50 | R32: =IF(P32=0,"",P32/Q32) -> 31.24 | S32: 20000 | T32: =IF(J32=0,"",J32+M32+P32) -> 18883 | U32: =IF(T32="","",K32+N32+Q32) -> 135 | V32: =IF(U32="","",T32/U32) -> 139.87407 | W32: =IFERROR(T32-S32,"") -> -1117 | X32: =IF(S32=0,"",T32/S32) -> 0.94415
C33: Growth | D33: =D30-D31 -> -57776 | G33: 30 | H33: =IF(H32<$D$9,H32+1,"EOM") -> 45746 | I33: =TEXT(H33,"DDD") -> Sun | J33: 18000 | K33: 36 | L33: =IF(J33=0,"",J33/K33) -> 500 | M33: 6548 | N33: 46 | O33: =IF(M33=0,"",M33/N33) -> 142.34783 | P33: 1995 | Q33: 40 | R33: =IF(P33=0,"",P33/Q33) -> 49.875 | S33: 20000 | T33: =IF(J33=0,"",J33+M33+P33) -> 26543 | U33: =IF(T33="","",K33+N33+Q33) -> 122 | V33: =IF(U33="","",T33/U33) -> 217.56557 | W33: =IFERROR(T33-S33,"") -> 6543 | X33: =IF(S33=0,"",T33/S33) -> 1.32715
D34: =(D30-D31)/D31 -> -0.081372012 | G34: 31 | H34: =IF(H33<$D$9,H33+1,"EOM") -> 45747 | I34: =TEXT(H34,"DDD") -> Mon | J34: 17000 | K34: 34 | L34: =IF(J34=0,"",J34/K34) -> 500 | M34: 4512 | N34: 21 | O34: =IF(M34=0,"",M34/N34) -> 214.85714 | P34: 2400 | Q34: 46 | R34: =IF(P34=0,"",P34/Q34) -> 52.173913 | S34: 20000 | T34: =IF(J34=0,"",J34+M34+P34) -> 23912 | U34: =IF(T34="","",K34+N34+Q34) -> 101 | V34: =IF(U34="","",T34/U34) -> 236.75248 | W34: =IFERROR(T34-S34,"") -> 3912 | X34: =IF(S34=0,"",T34/S34) -> 1.1956
G35: Totals | J35: =SUM(J4:J34) -> 398000 | K35: =SUM(K4:K34) -> 1216 | M35: =SUM(M4:M34) -> 180483 | N35: =SUM(N4:N34) -> 1213 | P35: =SUM(P4:P34) -> 73764 | Q35: =SUM(Q4:Q34) -> 1238 | S35: =SUM(S4:S34) -> 620000 | T35: =SUM(T4:T34) -> 652247 | U35: =SUM(U4:U34) -> 3667 | W35: =SUM(W4:W34) -> 32247

Sheet APR
D2: DASHBOARD | G2: Daily Sales Report (Dine in, Take Away, Delivery) | S2: Consolidated
C3: Month | D3: April | G3: S.no | H3: Date | I3: Day | J3: Dine In sales | K3: Dine In Tickets | L3: APC / APT | M3: Take Away sales | N3: Take Away Tickets | O3: APC / APT | P3: Delivery sales | Q3: Delivery Tickets | R3: APC / APT | S3: Target Sales | T3: Total Sales | U3: Total Ticket | V3: APC / APT | W3: Target vs Achieved | X3: %
G4: 1 | H4: =D7 -> 45748 | I4: =TEXT(H4,"DDD") -> Tue | J4: 15000 | K4: 24 | L4: =IF(J4=0,"",J4/K4) -> 625 | M4: 7000 | N4: 35 | O4: =IF(M4=0,"",M4/N4) -> 200 | P4: 6000 | Q4: 36 | R4: =IF(P4=0,"",P4/Q4) -> 166.66667 | S4: 20000 | T4: =IF(J4=0,"",J4+M4+P4) -> 28000 | U4: =IF(T4="","",K4+N4+Q4) -> 95 | V4: =IF(U4="","",T4/U4) -> 294.73684 | W4: =IFERROR(T4-S4,"") -> 8000 | X4: =IF(S4=0,"",T4/S4) -> 1.4
C5: Year | D5: 2025 | G5: 2 | H5: =IF(H4<$D$9,H4+1,"EOM") -> 45749 | I5: =TEXT(H5,"DDD") -> Wed | J5: 12000 | K5: 45 | L5: =IF(J5=0,"",J5/K5) -> 266.66667 | M5: 5500 | N5: 50 | O5: =IF(M5=0,"",M5/N5) -> 110 | P5: 5321 | Q5: 34 | R5: =IF(P5=0,"",P5/Q5) -> 156.5 | S5: 20000 | T5: =IF(J5=0,"",J5+M5+P5) -> 22821 | U5: =IF(T5="","",K5+N5+Q5) -> 129 | V5: =IF(U5="","",T5/U5) -> 176.90698 | W5: =IFERROR(T5-S5,"") -> 2821 | X5: =IF(S5=0,"",T5/S5) -> 1.14105
G6: 3 | H6: =IF(H5<$D$9,H5+1,"EOM") -> 45750 | I6: =TEXT(H6,"DDD") -> Thu | J6: 14000 | K6: 46 | L6: =IF(J6=0,"",J6/K6) -> 304.34783 | M6: 5600 | N6: 40 | O6: =IF(M6=0,"",M6/N6) -> 140 | P6: 1200 | Q6: 24 | R6: =IF(P6=0,"",P6/Q6) -> 50 | S6: 20000 | T6: =IF(J6=0,"",J6+M6+P6) -> 20800 | U6: =IF(T6="","",K6+N6+Q6) -> 110 | V6: =IF(U6="","",T6/U6) -> 189.09091 | W6: =IFERROR(T6-S6,"") -> 800 | X6: =IF(S6=0,"",T6/S6) -> 1.04
C7: Start Date | D7: =DATEVALUE("1"& D3 & D5) -> 45748 | G7: 4 | H7: =IF(H6<$D$9,H6+1,"EOM") -> 45751 | I7: =TEXT(H7,"DDD") -> Fri | J7: 11000 | K7: 35 | L7: =IF(J7=0,"",J7/K7) -> 314.28571 | M7: 5800 | N7: 36 | O7: =IF(M7=0,"",M7/N7) -> 161.11111 | P7: 2200 | Q7: 45 | R7: =IF(P7=0,"",P7/Q7) -> 48.888889 | S7: 20000 | T7: =IF(J7=0,"",J7+M7+P7) -> 19000 | U7: =IF(T7="","",K7+N7+Q7) -> 116 | V7: =IF(U7="","",T7/U7) -> 163.7931 | W7: =IFERROR(T7-S7,"") -> -1000 | X7: =IF(S7=0,"",T7/S7) -> 0.95
G8: 5 | H8: =IF(H7<$D$9,H7+1,"EOM") -> 45752 | I8: =TEXT(H8,"DDD") -> Sat | J8: 10000 | K8: 50 | L8: =IF(J8=0,"",J8/K8) -> 200 | M8: 7100 | N8: 34 | O8: =IF(M8=0,"",M8/N8) -> 208.82353 | P8: 2415 | Q8: 46 | R8: =IF(P8=0,"",P8/Q8) -> 52.5 | S8: 20000 | T8: =IF(J8=0,"",J8+M8+P8) -> 19515 | U8: =IF(T8="","",K8+N8+Q8) -> 130 | V8: =IF(U8="","",T8/U8) -> 150.11538 | W8: =IFERROR(T8-S8,"") -> -485 | X8: =IF(S8=0,"",T8/S8) -> 0.97575
C9: End Date | D9: =EOMONTH(D7, 0) -> 45777 | G9: 6 | H9: =IF(H8<$D$9,H8+1,"EOM") -> 45753 | I9: =TEXT(H9,"DDD") -> Sun | J9: 16000 | K9: 40 | L9: =IF(J9=0,"",J9/K9) -> 400 | M9: 6500 | N9: 24 | O9: =IF(M9=0,"",M9/N9) -> 270.83333 | P9: 2561 | Q9: 35 | R9: =IF(P9=0,"",P9/Q9) -> 73.171429 | S9: 20000 | T9: =IF(J9=0,"",J9+M9+P9) -> 25061 | U9: =IF(T9="","",K9+N9+Q9) -> 99 | V9: =IF(U9="","",T9/U9) -> 253.14141 | W9: =IFERROR(T9-S9,"") -> 5061 | X9: =IF(S9=0,"",T9/S9) -> 1.25305
G10: 7 | H10: =IF(H9<$D$9,H9+1,"EOM") -> 45754 | I10: =TEXT(H10,"DDD") -> Mon | J10: 12000 | K10: 36 | L10: =IF(J10=0,"",J10/K10) -> 333.33333 | M10: 6200 | N10: 45 | O10: =IF(M10=0,"",M10/N10) -> 137.77778 | P10: 3214 | Q10: 50 | R10: =IF(P10=0,"",P10/Q10) -> 64.28 | S10: 20000 | T10: =IF(J10=0,"",J10+M10+P10) -> 21414 | U10: =IF(T10="","",K10+N10+Q10) -> 131 | V10: =IF(U10="","",T10/U10) -> 163.46565 | W10: =IFERROR(T10-S10,"") -> 1414 | X10: =IF(S10=0,"",T10/S10) -> 1.0707
C11: Total Days | D11: =COUNT(H4:H34) -> 30 | G11: 8 | H11: =IF(H10<$D$9,H10+1,"EOM") -> 45755 | I11: =TEXT(H11,"DDD") -> Tue | J11: 11000 | K11: 34 | L11: =IF(J11=0,"",J11/K11) -> 323.52941 | M11: 4500 | N11: 46 | O11: =IF(M11=0,"",M11/N11) -> 97.826087 | P11: 2315 | Q11: 40 | R11: =IF(P11=0,"",P11/Q11) -> 57.875 | S11: 20000 | T11: =IF(J11=0,"",J11+M11+P11) -> 17815 | U11: =IF(T11="","",K11+N11+Q11) -> 120 | V11: =IF(U11="","",T11/U11) -> 148.45833 | W11: =IFERROR(T11-S11,"") -> -2185 | X11: =IF(S11=0,"",T11/S11) -> 0.89075
G12: 9 | H12: =IF(H11<$D$9,H11+1,"EOM") -> 45756 | I12: =TEXT(H12,"DDD") -> Wed | J12: 15000 | K12: 24 | L12: =IF(J12=0,"",J12/K12) -> 625 | M12: 7200 | N12: 35 | O12: =IF(M12=0,"",M12/N12) -> 205.71429 | P12: 3524 | Q12: 36 | R12: =IF(P12=0,"",P12/Q12) -> 97.888889 | S12: 20000 | T12: =IF(J12=0,"",J12+M12+P12) -> 25724 | U12: =IF(T12="","",K12+N12+Q12) -> 95 | V12: =IF(U12="","",T12/U12) -> 270.77895 | W12: =IFERROR(T12-S12,"") -> 5724 | X12: =IF(S12=0,"",T12/S12) -> 1.2862
C13: Total Saturday | D13: =COUNTIF(I4:I34,"Sat") -> 4 | G13: 10 | H13: =IF(H12<$D$9,H12+1,"EOM") -> 45757 | I13: =TEXT(H13,"DDD") -> Thu | J13: 12000 | K13: 45 | L13: =IF(J13=0,"",J13/K13) -> 266.66667 | M13: 6900 | N13: 50 | O13: =IF(M13=0,"",M13/N13) -> 138 | P13: 3621 | Q13: 34 | R13: =IF(P13=0,"",P13/Q13) -> 106.5 | S13: 20000 | T13: =IF(J13=0,"",J13+M13+P13) -> 22521 | U13: =IF(T13="","",K13+N13+Q13) -> 129 | V13: =IF(U13="","",T13/U13) -> 174.5814 | W13: =IFERROR(T13-S13,"") -> 2521 | X13: =IF(S13=0,"",T13/S13) -> 1.12605
C14: Total Sunday | D14: =COUNTIF(I4:I34,"Sun") -> 4 | G14: 11 | H14: =IF(H13<$D$9,H13+1,"EOM") -> 45758 | I14: =TEXT(H14,"DDD") -> Fri | J14: 14000 | K14: 46 | L14: =IF(J14=0,"",J14/K14) -> 304.34783 | M14: 5900 | N14: 40 | O14: =IF(M14=0,"",M14/N14) -> 147.5 | P14: 1200 | Q14: 45 | R14: =IF(P14=0,"",P14/Q14) -> 26.666667 | S14: 20000 | T14: =IF(J14=0,"",J14+M14+P14) -> 21100 | U14: =IF(T14="","",K14+N14+Q14) -> 131 | V14: =IF(U14="","",T14/U14) -> 161.0687 | W14: =IFERROR(T14-S14,"") -> 1100 | X14: =IF(S14=0,"",T14/S14) -> 1.055
G15: 12 | H15: =IF(H14<$D$9,H14+1,"EOM") -> 45759 | I15: =TEXT(H15,"DDD") -> Sat | J15: 11000 | K15: 35 | L15: =IF(J15=0,"",J15/K15) -> 314.28571 | M15: 7500 | N15: 36 | O15: =IF(M15=0,"",M15/N15) -> 208.33333 | P15: 850 | Q15: 46 | R15: =IF(P15=0,"",P15/Q15) -> 18.478261 | S15: 20000 | T15: =IF(J15=0,"",J15+M15+P15) -> 19350 | U15: =IF(T15="","",K15+N15+Q15) -> 117 | V15: =IF(U15="","",T15/U15) -> 165.38462 | W15: =IFERROR(T15-S15,"") -> -650 | X15: =IF(S15=0,"",T15/S15) -> 0.9675
C16: Highest sales for the day | D16: =MAX(T4:T34) -> 28000 | G16: 13 | H16: =IF(H15<$D$9,H15+1,"EOM") -> 45760 | I16: =TEXT(H16,"DDD") -> Sun | J16: 10000 | K16: 50 | L16: =IF(J16=0,"",J16/K16) -> 200 | M16: 5800 | N16: 34 | O16: =IF(M16=0,"",M16/N16) -> 170.58824 | P16: 1421 | Q16: 35 | R16: =IF(P16=0,"",P16/Q16) -> 40.6 | S16: 20000 | T16: =IF(J16=0,"",J16+M16+P16) -> 17221 | U16: =IF(T16="","",K16+N16+Q16) -> 119 | V16: =IF(U16="","",T16/U16) -> 144.71429 | W16: =IFERROR(T16-S16,"") -> -2779 | X16: =IF(S16=0,"",T16/S16) -> 0.86105
G17: 14 | H17: =IF(H16<$D$9,H16+1,"EOM") -> 45761 | I17: =TEXT(H17,"DDD") -> Mon | J17: 16000 | K17: 40 | L17: =IF(J17=0,"",J17/K17) -> 400 | M17: 4500 | N17: 45 | O17: =IF(M17=0,"",M17/N17) -> 100 | P17: 1562 | Q17: 50 | R17: =IF(P17=0,"",P17/Q17) -> 31.24 | S17: 20000 | T17: =IF(J17=0,"",J17+M17+P17) -> 22062 | U17: =IF(T17="","",K17+N17+Q17) -> 135 | V17: =IF(U17="","",T17/U17) -> 163.42222 | W17: =IFERROR(T17-S17,"") -> 2062 | X17: =IF(S17=0,"",T17/S17) -> 1.1031
C18: Lowest sales for the day | D18: =MIN(T4:T34) -> 16300 | G18: 15 | H18: =IF(H17<$D$9,H17+1,"EOM") -> 45762 | I18: =TEXT(H18,"DDD") -> Tue | J18: 12000 | K18: 36 | L18: =IF(J18=0,"",J18/K18) -> 333.33333 | M18: 4900 | N18: 46 | O18: =IF(M18=0,"",M18/N18) -> 106.52174 | P18: 1900 | Q18: 40 | R18: =IF(P18=0,"",P18/Q18) -> 47.5 | S18: 20000 | T18: =IF(J18=0,"",J18+M18+P18) -> 18800 | U18: =IF(T18="","",K18+N18+Q18) -> 122 | V18: =IF(U18="","",T18/U18) -> 154.09836 | W18: =IFERROR(T18-S18,"") -> -1200 | X18: =IF(S18=0,"",T18/S18) -> 0.94
G19: 16 | H19: =IF(H18<$D$9,H18+1,"EOM") -> 45763 | I19: =TEXT(H19,"DDD") -> Wed | J19: 11000 | K19: 34 | L19: =IF(J19=0,"",J19/K19) -> 323.52941 | M19: 3200 | N19: 35 | O19: =IF(M19=0,"",M19/N19) -> 91.428571 | P19: 2100 | Q19: 36 | R19: =IF(P19=0,"",P19/Q19) -> 58.333333 | S19: 20000 | T19: =IF(J19=0,"",J19+M19+P19) -> 16300 | U19: =IF(T19="","",K19+N19+Q19) -> 105 | V19: =IF(U19="","",T19/U19) -> 155.2381 | W19: =IFERROR(T19-S19,"") -> -3700 | X19: =IF(S19=0,"",T19/S19) -> 0.815
C20: Target Achieved | D20: =IF(T35>S35,"Yes","No") -> Yes | G20: 17 | H20: =IF(H19<$D$9,H19+1,"EOM") -> 45764 | I20: =TEXT(H20,"DDD") -> Thu | J20: 15000 | K20: 24 | L20: =IF(J20=0,"",J20/K20) -> 625 | M20: 4600 | N20: 50 | O20: =IF(M20=0,"",M20/N20) -> 92 | P20: 2135 | Q20: 34 | R20: =IF(P20=0,"",P20/Q20) -> 62.794118 | S20: 20000 | T20: =IF(J20=0,"",J20+M20+P20) -> 21735 | U20: =IF(T20="","",K20+N20+Q20) -> 108 | V20: =IF(U20="","",T20/U20) -> 201.25 | W20: =IFERROR(T20-S20,"") -> 1735 | X20: =IF(S20=0,"",T20/S20) -> 1.08675
G21: 18 | H21: =IF(H20<$D$9,H20+1,"EOM") -> 45765 | I21: =TEXT(H21,"DDD") -> Fri | J21: 12000 | K21: 45 | L21: =IF(J21=0,"",J21/K21) -> 266.66667 | M21: 5600 | N21: 40 | O21: =IF(M21=0,"",M21/N21) -> 140 | P21: 2362 | Q21: 24 | R21: =IF(P21=0,"",P21/Q21) -> 98.416667 | S21: 20000 | T21: =IF(J21=0,"",J21+M21+P21) -> 19962 | U21: =IF(T21="","",K21+N21+Q21) -> 109 | V21: =IF(U21="","",T21/U21) -> 183.13761 | W21: =IFERROR(T21-S21,"") -> -38 | X21: =IF(S21=0,"",T21/S21) -> 0.9981
C22: Sales till date | D22: =T35 -> 652247 | G22: 19 | H22: =IF(H21<$D$9,H21+1,"EOM") -> 45766 | I22: =TEXT(H22,"DDD") -> Sat | J22: 14000 | K22: 46 | L22: =IF(J22=0,"",J22/K22) -> 304.34783 | M22: 4500 | N22: 36 | O22: =IF(M22=0,"",M22/N22) -> 125 | P22: 3521 | Q22: 45 | R22: =IF(P22=0,"",P22/Q22) -> 78.244444 | S22: 20000 | T22: =IF(J22=0,"",J22+M22+P22) -> 22021 | U22: =IF(T22="","",K22+N22+Q22) -> 127 | V22: =IF(U22="","",T22/U22) -> 173.3937 | W22: =IFERROR(T22-S22,"") -> 2021 | X22: =IF(S22=0,"",T22/S22) -> 1.10105
G23: 20 | H23: =IF(H22<$D$9,H22+1,"EOM") -> 45767 | I23: =TEXT(H23,"DDD") -> Sun | J23: 11000 | K23: 35 | L23: =IF(J23=0,"",J23/K23) -> 314.28571 | M23: 7500 | N23: 34 | O23: =IF(M23=0,"",M23/N23) -> 220.58824 | P23: 3254 | Q23: 46 | R23: =IF(P23=0,"",P23/Q23) -> 70.73913 | S23: 20000 | T23: =IF(J23=0,"",J23+M23+P23) -> 21754 | U23: =IF(T23="","",K23+N23+Q23) -> 115 | V23: =IF(U23="","",T23/U23) -> 189.16522 | W23: =IFERROR(T23-S23,"") -> 1754 | X23: =IF(S23=0,"",T23/S23) -> 1.0877
C24: Average sales | D24: =AVERAGE(T4:T34) -> 21040.226 | G24: 21 | H24: =IF(H23<$D$9,H23+1,"EOM") -> 45768 | I24: =TEXT(H24,"DDD") -> Mon | J24: 10000 | K24: 50 | L24: =IF(J24=0,"",J24/K24) -> 200 | M24: 5900 | N24: 24 | O24: =IF(M24=0,"",M24/N24) -> 245.83333 | P24: 2651 | Q24: 35 | R24: =IF(P24=0,"",P24/Q24) -> 75.742857 | S24: 20000 | T24: =IF(J24=0,"",J24+M24+P24) -> 18551 | U24: =IF(T24="","",K24+N24+Q24) -> 109 | V24: =IF(U24="","",T24/U24) -> 170.19266 | W24: =IFERROR(T24-S24,"") -> -1449 | X24: =IF(S24=0,"",T24/S24) -> 0.92755
G25: 22 | H25: =IF(H24<$D$9,H24+1,"EOM") -> 45769 | I25: =TEXT(H25,"DDD") -> Tue | J25: 16000 | K25: 40 | L25: =IF(J25=0,"",J25/K25) -> 400 | M25: 6200 | N25: 45 | O25: =IF(M25=0,"",M25/N25) -> 137.77778 | P25: 2548 | Q25: 50 | R25: =IF(P25=0,"",P25/Q25) -> 50.96 | S25: 20000 | T25: =IF(J25=0,"",J25+M25+P25) -> 24748 | U25: =IF(T25="","",K25+N25+Q25) -> 135 | V25: =IF(U25="","",T25/U25) -> 183.31852 | W25: =IFERROR(T25-S25,"") -> 4748 | X25: =IF(S25=0,"",T25/S25) -> 1.2374
